Workbook

Sheet Corporate
C2: Margin
C3: Fuel
I4: STANDARD | Q4: EXPRESS
K5: Best Price | L5: Gross Margin | M5: Final Price | N5: Courrier | S5: Best Price | T5: Gross Margin | U5: Final Price | V5: Courrier
H6: 0.5 | I6: =VLOOKUP($H6,UPS!$B$10:$H$106,((VLOOKUP($E$10,Areas!$B$4:$D$200,2,FALSE))+1),FALSE) -> 18.02 | J6: =VLOOKUP($H6,FedEx!$B$10:$I$96,((VLOOKUP($E$10,Areas!$B$4:$D$200,3,FALSE))+1),FALSE) -> 35.49 | K6: =MINA(I6:J6) -> 18.02 | L6: =$D$2 | M6: =K6/(1-L6) -> 18.02 | N6: =IF(I6=K6,"UPS",IF(J6=K6,"FedEx",IF(#REF!=K6,"TNT",0))) -> UPS | P6: 0.5 | Q6: =VLOOKUP($P6, UPS!$J$10:$P$106,((VLOOKUP($E$10,Areas!$B$4:$D$200,2,FALSE))+1),FALSE) -> 19.2 | R6: =VLOOKUP($P6, FedEx!$K$10:$R$96,((VLOOKUP($E$10,Areas!$B$4:$D$200,3,FALSE))+1),FALSE) -> 32.45 | S6: =MINA(Q6:R6) -> 19.2 | T6: =$D$2 | U6: =S6/(1-T6) -> 19.2 | V6: =IF(Q6=S6,"UPS",IF(R6=S6,"FedEx",IF(#REF!=S6,"TNT",0))) -> UPS
H7: 1 | I7: =VLOOKUP($H7,UPS!$B$10:$H$106,((VLOOKUP($E$10,Areas!$B$4:$D$200,2,FALSE))+1),FALSE) -> 21.03 | J7: =VLOOKUP($H7,FedEx!$B$10:$I$96,((VLOOKUP($E$10,Areas!$B$4:$D$200,3,FALSE))+1),FALSE) -> 41.3 | K7: =MINA(I7:J7) -> 21.03 | L7: =$D$2 | M7: =K7/(1-L7) -> 21.03 | N7: =IF(I7=K7,"UPS",IF(J7=K7,"FedEx",IF(#REF!=K7,"TNT",0))) -> UPS | P7: 1 | Q7: =VLOOKUP($P7, UPS!$J$10:$P$106,((VLOOKUP($E$10,Areas!$B$4:$D$200,2,FALSE))+1),FALSE) -> 22.35 | R7: =VLOOKUP($P7, FedEx!$K$10:$R$96,((VLOOKUP($E$10,Areas!$B$4:$D$200,3,FALSE))+1),FALSE) -> 37.7 | S7: =MINA(Q7:R7) -> 22.35 | T7: =$D$2 | U7: =S7/(1-T7) -> 22.35 | V7: =IF(Q7=S7,"UPS",IF(R7=S7,"FedEx",IF(#REF!=S7,"TNT",0))) -> UPS
H8: 1.5 | I8: =VLOOKUP($H8,UPS!$B$10:$H$106,((VLOOKUP($E$10,Areas!$B$4:$D$200,2,FALSE))+1),FALSE) -> 24.04 | J8: =VLOOKUP($H8,FedEx!$B$10:$I$96,((VLOOKUP($E$10,Areas!$B$4:$D$200,3,FALSE))+1),FALSE) -> 47.11 | K8: =MINA(I8:J8) -> 24.04 | L8: =$D$2 | M8: =K8/(1-L8) -> 24.04 | N8: =IF(I8=K8,"UPS",IF(J8=K8,"FedEx",IF(#REF!=K8,"TNT",0))) -> UPS | P8: 1.5 | Q8: =VLOOKUP($P8, UPS!$J$10:$P$106,((VLOOKUP($E$10,Areas!$B$4:$D$200,2,FALSE))+1),FALSE) -> 25.58 | R8: =VLOOKUP($P8, FedEx!$K$10:$R$96,((VLOOKUP($E$10,Areas!$B$4:$D$200,3,FALSE))+1),FALSE) -> 42.94 | S8: =MINA(Q8:R8) -> 25.58 | T8: =$D$2 | U8: =S8/(1-T8) -> 25.58 | V8: =IF(Q8=S8,"UPS",IF(R8=S8,"FedEx",IF(#REF!=S8,"TNT",0))) -> UPS
H9: 2 | I9: =VLOOKUP($H9,UPS!$B$10:$H$106,((VLOOKUP($E$10,Areas!$B$4:$D$200,2,FALSE))+1),FALSE) -> 27.27 | J9: =VLOOKUP($H9,FedEx!$B$10:$I$96,((VLOOKUP($E$10,Areas!$B$4:$D$200,3,FALSE))+1),FALSE) -> 52.92 | K9: =MINA(I9:J9) -> 27.27 | L9: =$D$2 | M9: =K9/(1-L9) -> 27.27 | N9: =IF(I9=K9,"UPS",IF(J9=K9,"FedEx",IF(#REF!=K9,"TNT",0))) -> UPS | P9: 2 | Q9: =VLOOKUP($P9, UPS!$J$10:$P$106,((VLOOKUP($E$10,Areas!$B$4:$D$200,2,FALSE))+1),FALSE) -> 29.02 | R9: =VLOOKUP($P9, FedEx!$K$10:$R$96,((VLOOKUP($E$10,Areas!$B$4:$D$200,3,FALSE))+1),FALSE) -> 48.19 | S9: =MINA(Q9:R9) -> 29.02 | T9: =$D$2 | U9: =S9/(1-T9) -> 29.02 | V9: =IF(Q9=S9,"UPS",IF(R9=S9,"FedEx",IF(#REF!=S9,"TNT",0))) -> UPS
C10: Country: | E10: Estados Unidos | H10: 2.5 | I10: =VLOOKUP($H10,UPS!$B$10:$H$106,((VLOOKUP($E$10,Areas!$B$4:$D$200,2,FALSE))+1),FALSE) -> 30.02 | J10: =VLOOKUP($H10,FedEx!$B$10:$I$96,((VLOOKUP($E$10,Areas!$B$4:$D$200,3,FALSE))+1),FALSE) -> 58.73 | K10: =MINA(I10:J10) -> 30.02 | L10: =$D$2 | M10: =K10/(1-L10) -> 30.02 | N10: =IF(I10=K10,"UPS",IF(J10=K10,"FedEx",IF(#REF!=K10,"TNT",0))) -> UPS | P10: 2.5 | Q10: =VLOOKUP($P10, UPS!$J$10:$P$106,((VLOOKUP($E$10,Areas!$B$4:$D$200,2,FALSE))+1),FALSE) -> 31.94 | R10: =VLOOKUP($P10, FedEx!$K$10:$R$96,((VLOOKUP($E$10,Areas!$B$4:$D$200,3,FALSE))+1),FALSE) -> 53.44 | S10: =MINA(Q10:R10) -> 31.94 | T10: =$D$2 | U10: =S10/(1-T10) -> 31.94 | V10: =IF(Q10=S10,"UPS",IF(R10=S10,"FedEx",IF(#REF!=S10,"TNT",0))) -> UPS
H11: 3 | I11: =VLOOKUP($H11,UPS!$B$10:$H$106,((VLOOKUP($E$10,Areas!$B$4:$D$200,2,FALSE))+1),FALSE) -> 31.79 | J11: =VLOOKUP($H11,FedEx!$B$10:$I$96,((VLOOKUP($E$10,Areas!$B$4:$D$200,3,FALSE))+1),FALSE) -> 64.48 | K11: =MINA(I11:J11) -> 31.79 | L11: =$D$2 | M11: =K11/(1-L11) -> 31.79 | N11: =IF(I11=K11,"UPS",IF(J11=K11,"FedEx",IF(#REF!=K11,"TNT",0))) -> UPS | P11: 3 | Q11: =VLOOKUP($P11, UPS!$J$10:$P$106,((VLOOKUP($E$10,Areas!$B$4:$D$200,2,FALSE))+1),FALSE) -> 33.83 | R11: =VLOOKUP($P11, FedEx!$K$10:$R$96,((VLOOKUP($E$10,Areas!$B$4:$D$200,3,FALSE))+1),FALSE) -> 58.72 | S11: =MINA(Q11:R11) -> 33.83 | T11: =$D$2 | U11: =S11/(1-T11) -> 33.83 | V11: =IF(Q11=S11,"UPS",IF(R11=S11,"FedEx",IF(#REF!=S11,"TNT",0))) -> UPS
D12: Standard | E12: Express | H12: 3.5 | I12: =VLOOKUP($H12,UPS!$B$10:$H$106,((VLOOKUP($E$10,Areas!$B$4:$D$200,2,FALSE))+1),FALSE) -> 33.75 | J12: =VLOOKUP($H12,FedEx!$B$10:$I$96,((VLOOKUP($E$10,Areas!$B$4:$D$200,3,FALSE))+1),FALSE) -> 70.23 | K12: =MINA(I12:J12) -> 33.75 | L12: =$D$2 | M12: =K12/(1-L12) -> 33.75 | N12: =IF(I12=K12,"UPS",IF(J12=K12,"FedEx",IF(#REF!=K12,"TNT",0))) -> UPS | P12: 3.5 | Q12: =VLOOKUP($P12, UPS!$J$10:$P$106,((VLOOKUP($E$10,Areas!$B$4:$D$200,2,FALSE))+1),FALSE) -> 35.93 | R12: =VLOOKUP($P12, FedEx!$K$10:$R$96,((VLOOKUP($E$10,Areas!$B$4:$D$200,3,FALSE))+1),FALSE) -> 64 | S12: =MINA(Q12:R12) -> 35.93 | T12: =$D$2 | U12: =S12/(1-T12) -> 35.93 | V12: =IF(Q12=S12,"UPS",IF(R12=S12,"FedEx",IF(#REF!=S12,"TNT",0))) -> UPS
C13: 0.5 | D13: =M6+(M6*$D$3) -> 18.02 | E13: =U6+(U6*$D$3) -> 19.2 | H13: 4 | I13: =VLOOKUP($H13,UPS!$B$10:$H$106,((VLOOKUP($E$10,Areas!$B$4:$D$200,2,FALSE))+1),FALSE) -> 35.74 | J13: =VLOOKUP($H13,FedEx!$B$10:$I$96,((VLOOKUP($E$10,Areas!$B$4:$D$200,3,FALSE))+1),FALSE) -> 75.97 | K13: =MINA(I13:J13) -> 35.74 | L13: =$D$2 | M13: =K13/(1-L13) -> 35.74 | N13: =IF(I13=K13,"UPS",IF(J13=K13,"FedEx",IF(#REF!=K13,"TNT",0))) -> UPS | P13: 4 | Q13: =VLOOKUP($P13, UPS!$J$10:$P$106,((VLOOKUP($E$10,Areas!$B$4:$D$200,2,FALSE))+1),FALSE) -> 38.03 | R13: =VLOOKUP($P13, FedEx!$K$10:$R$96,((VLOOKUP($E$10,Areas!$B$4:$D$200,3,FALSE))+1),FALSE) -> 69.28 | S13: =MINA(Q13:R13) -> 38.03 | T13: =$D$2 | U13: =S13/(1-T13) -> 38.03 | V13: =IF(Q13=S13,"UPS",IF(R13=S13,"FedEx",IF(#REF!=S13,"TNT",0))) -> UPS
C14: 1 | D14: =M7+(M7*$D$3) -> 21.03 | E14: =U7+(U7*$D$3) -> 22.35 | H14: 4.5 | I14: =VLOOKUP($H14,UPS!$B$10:$H$106,((VLOOKUP($E$10,Areas!$B$4:$D$200,2,FALSE))+1),FALSE) -> 37.86 | J14: =VLOOKUP($H14,FedEx!$B$10:$I$96,((VLOOKUP($E$10,Areas!$B$4:$D$200,3,FALSE))+1),FALSE) -> 81.72 | K14: =MINA(I14:J14) -> 37.86 | L14: =$D$2 | M14: =K14/(1-L14) -> 37.86 | N14: =IF(I14=K14,"UPS",IF(J14=K14,"FedEx",IF(#REF!=K14,"TNT",0))) -> UPS | P14: 4.5 | Q14: =VLOOKUP($P14, UPS!$J$10:$P$106,((VLOOKUP($E$10,Areas!$B$4:$D$200,2,FALSE))+1),FALSE) -> 40.27 | R14: =VLOOKUP($P14, FedEx!$K$10:$R$96,((VLOOKUP($E$10,Areas!$B$4:$D$200,3,FALSE))+1),FALSE) -> 74.56 | S14: =MINA(Q14:R14) -> 40.27 | T14: =$D$2 | U14: =S14/(1-T14) -> 40.27 | V14: =IF(Q14=S14,"UPS",IF(R14=S14,"FedEx",IF(#REF!=S14,"TNT",0))) -> UPS
C15: 1.5 | D15: =M8+(M8*$D$3) -> 24.04 | E15: =U8+(U8*$D$3) -> 25.58 | H15: 5 | I15: =VLOOKUP($H15,UPS!$B$10:$H$106,((VLOOKUP($E$10,Areas!$B$4:$D$200,2,FALSE))+1),FALSE) -> 40.07 | J15: =VLOOKUP($H15,FedEx!$B$10:$I$96,((VLOOKUP($E$10,Areas!$B$4:$D$200,3,FALSE))+1),FALSE) -> 87.46 | K15: =MINA(I15:J15) -> 40.07 | L15: =$D$2 | M15: =K15/(1-L15) -> 40.07 | N15: =IF(I15=K15,"UPS",IF(J15=K15,"FedEx",IF(#REF!=K15,"TNT",0))) -> UPS | P15: 5 | Q15: =VLOOKUP($P15, UPS!$J$10:$P$106,((VLOOKUP($E$10,Areas!$B$4:$D$200,2,FALSE))+1),FALSE) -> 42.64 | R15: =VLOOKUP($P15, FedEx!$K$10:$R$96,((VLOOKUP($E$10,Areas!$B$4:$D$200,3,FALSE))+1),FALSE) -> 79.84 | S15: =MINA(Q15:R15) -> 42.64 | T15: =$D$2 | U15: =S15/(1-T15) -> 42.64 | V15: =IF(Q15=S15,"UPS",IF(R15=S15,"FedEx",IF(#REF!=S15,"TNT",0))) -> UPS
C16: 2 | D16: =M9+(M9*$D$3) -> 27.27 | E16: =U9+(U9*$D$3) -> 29.02 | H16: 5.5 | I16: =VLOOKUP($H16,UPS!$B$10:$H$106,((VLOOKUP($E$10,Areas!$B$4:$D$200,2,FALSE))+1),FALSE) -> 41.99 | J16: =VLOOKUP($H16,FedEx!$B$10:$I$96,((VLOOKUP($E$10,Areas!$B$4:$D$200,3,FALSE))+1),FALSE) -> 91.18 | K16: =MINA(I16:J16) -> 41.99 | L16: =$D$2 | M16: =K16/(1-L16) -> 41.99 | N16: =IF(I16=K16,"UPS",IF(J16=K16,"FedEx",IF(#REF!=K16,"TNT",0))) -> UPS | P16: 5.5 | Q16: =VLOOKUP($P16, UPS!$J$10:$P$106,((VLOOKUP($E$10,Areas!$B$4:$D$200,2,FALSE))+1),FALSE) -> 44.67 | R16: =VLOOKUP($P16, FedEx!$K$10:$R$96,((VLOOKUP($E$10,Areas!$B$4:$D$200,3,FALSE))+1),FALSE) -> 83.19 | S16: =MINA(Q16:R16) -> 44.67 | T16: =$D$2 | U16: =S16/(1-T16) -> 44.67 | V16: =IF(Q16=S16,"UPS",IF(R16=S16,"FedEx",IF(#REF!=S16,"TNT",0))) -> UPS
C17: 2.5 | D17: =M10+(M10*$D$3) -> 30.02 | E17: =U10+(U10*$D$3) -> 31.94 | H17: 6 | I17: =VLOOKUP($H17,UPS!$B$10:$H$106,((VLOOKUP($E$10,Areas!$B$4:$D$200,2,FALSE))+1),FALSE) -> 44.07 | J17: =VLOOKUP($H17,FedEx!$B$10:$I$96,((VLOOKUP($E$10,Areas!$B$4:$D$200,3,FALSE))+1),FALSE) -> 94.9 | K17: =MINA(I17:J17) -> 44.07 | L17: =$D$2 | M17: =K17/(1-L17) -> 44.07 | N17: =IF(I17=K17,"UPS",IF(J17=K17,"FedEx",IF(#REF!=K17,"TNT",0))) -> UPS | P17: 6 | Q17: =VLOOKUP($P17, UPS!$J$10:$P$106,((VLOOKUP($E$10,Areas!$B$4:$D$200,2,FALSE))+1),FALSE) -> 46.88 | R17: =VLOOKUP($P17, FedEx!$K$10:$R$96,((VLOOKUP($E$10,Areas!$B$4:$D$200,3,FALSE))+1),FALSE) -> 86.55 | S17: =MINA(Q17:R17) -> 46.88 | T17: =$D$2 | U17: =S17/(1-T17) -> 46.88 | V17: =IF(Q17=S17,"UPS",IF(R17=S17,"FedEx",IF(#REF!=S17,"TNT",0))) -> UPS
C18: 3 | D18: =M11+(M11*$D$3) -> 31.79 | E18: =U11+(U11*$D$3) -> 33.83 | H18: 6.5 | I18: =VLOOKUP($H18,UPS!$B$10:$H$106,((VLOOKUP($E$10,Areas!$B$4:$D$200,2,FALSE))+1),FALSE) -> 45.77 | J18: =VLOOKUP($H18,FedEx!$B$10:$I$96,((VLOOKUP($E$10,Areas!$B$4:$D$200,3,FALSE))+1),FALSE) -> 98.62 | K18: =MINA(I18:J18) -> 45.77 | L18: =$D$2 | M18: =K18/(1-L18) -> 45.77 | N18: =IF(I18=K18,"UPS",IF(J18=K18,"FedEx",IF(#REF!=K18,"TNT",0))) -> UPS | P18: 6.5 | Q18: =VLOOKUP($P18, UPS!$J$10:$P$106,((VLOOKUP($E$10,Areas!$B$4:$D$200,2,FALSE))+1),FALSE) -> 48.69 | R18: =VLOOKUP($P18, FedEx!$K$10:$R$96,((VLOOKUP($E$10,Areas!$B$4:$D$200,3,FALSE))+1),FALSE) -> 89.9 | S18: =MINA(Q18:R18) -> 48.69 | T18: =$D$2 | U18: =S18/(1-T18) -> 48.69 | V18: =IF(Q18=S18,"UPS",IF(R18=S18,"FedEx",IF(#REF!=S18,"TNT",0))) -> UPS
C19: 3.5 | D19: =M12+(M12*$D$3) -> 33.75 | E19: =U12+(U12*$D$3) -> 35.93 | H19: 7 | I19: =VLOOKUP($H19,UPS!$B$10:$H$106,((VLOOKUP($E$10,Areas!$B$4:$D$200,2,FALSE))+1),FALSE) -> 47.71 | J19: =VLOOKUP($H19,FedEx!$B$10:$I$96,((VLOOKUP($E$10,Areas!$B$4:$D$200,3,FALSE))+1),FALSE) -> 102.34 | K19: =MINA(I19:J19) -> 47.71 | L19: =$D$2 | M19: =K19/(1-L19) -> 47.71 | N19: =IF(I19=K19,"UPS",IF(J19=K19,"FedEx",IF(#REF!=K19,"TNT",0))) -> UPS | P19: 7 | Q19: =VLOOKUP($P19, UPS!$J$10:$P$106,((VLOOKUP($E$10,Areas!$B$4:$D$200,2,FALSE))+1),FALSE) -> 50.73 | R19: =VLOOKUP($P19, FedEx!$K$10:$R$96,((VLOOKUP($E$10,Areas!$B$4:$D$200,3,FALSE))+1),FALSE) -> 93.26 | S19: =MINA(Q19:R19) -> 50.73 | T19: =$D$2 | U19: =S19/(1-T19) -> 50.73 | V19: =IF(Q19=S19,"UPS",IF(R19=S19,"FedEx",IF(#REF!=S19,"TNT",0))) -> UPS
C20: 4 | D20: =M13+(M13*$D$3) -> 35.74 | E20: =U13+(U13*$D$3) -> 38.03 | H20: 7.5 | I20: =VLOOKUP($H20,UPS!$B$10:$H$106,((VLOOKUP($E$10,Areas!$B$4:$D$200,2,FALSE))+1),FALSE) -> 49.87 | J20: =VLOOKUP($H20,FedEx!$B$10:$I$96,((VLOOKUP($E$10,Areas!$B$4:$D$200,3,FALSE))+1),FALSE) -> 106.05 | K20: =MINA(I20:J20) -> 49.87 | L20: =$D$2 | M20: =K20/(1-L20) -> 49.87 | N20: =IF(I20=K20,"UPS",IF(J20=K20,"FedEx",IF(#REF!=K20,"TNT",0))) -> UPS | P20: 7.5 | Q20: =VLOOKUP($P20, UPS!$J$10:$P$106,((VLOOKUP($E$10,Areas!$B$4:$D$200,2,FALSE))+1),FALSE) -> 53.05 | R20: =VLOOKUP($P20, FedEx!$K$10:$R$96,((VLOOKUP($E$10,Areas!$B$4:$D$200,3,FALSE))+1),FALSE) -> 96.61 | S20: =MINA(Q20:R20) -> 53.05 | T20: =$D$2 | U20: =S20/(1-T20) -> 53.05 | V20: =IF(Q20=S20,"UPS",IF(R20=S20,"FedEx",IF(#REF!=S20,"TNT",0))) -> UPS
C21: 4.5 | D21: =M14+(M14*$D$3) -> 37.86 | E21: =U14+(U14*$D$3) -> 40.27 | H21: 8 | I21: =VLOOKUP($H21,UPS!$B$10:$H$106,((VLOOKUP($E$10,Areas!$B$4:$D$200,2,FALSE))+1),FALSE) -> 51.75 | J21: =VLOOKUP($H21,FedEx!$B$10:$I$96,((VLOOKUP($E$10,Areas!$B$4:$D$200,3,FALSE))+1),FALSE) -> 109.77 | K21: =MINA(I21:J21) -> 51.75 | L21: =$D$2 | M21: =K21/(1-L21) -> 51.75 | N21: =IF(I21=K21,"UPS",IF(J21=K21,"FedEx",IF(#REF!=K21,"TNT",0))) -> UPS | P21: 8 | Q21: =VLOOKUP($P21, UPS!$J$10:$P$106,((VLOOKUP($E$10,Areas!$B$4:$D$200,2,FALSE))+1),FALSE) -> 55.03 | R21: =VLOOKUP($P21, FedEx!$K$10:$R$96,((VLOOKUP($E$10,Areas!$B$4:$D$200,3,FALSE))+1),FALSE) -> 99.97 | S21: =MINA(Q21:R21) -> 55.03 | T21: =$D$2 | U21: =S21/(1-T21) -> 55.03 | V21: =IF(Q21=S21,"UPS",IF(R21=S21,"FedEx",IF(#REF!=S21,"TNT",0))) -> UPS
C22: 5 | D22: =M15+(M15*$D$3) -> 40.07 | E22: =U15+(U15*$D$3) -> 42.64 | H22: 8.5 | I22: =VLOOKUP($H22,UPS!$B$10:$H$106,((VLOOKUP($E$10,Areas!$B$4:$D$200,2,FALSE))+1),FALSE) -> 53.53 | J22: =VLOOKUP($H22,FedEx!$B$10:$I$96,((VLOOKUP($E$10,Areas!$B$4:$D$200,3,FALSE))+1),FALSE) -> 113.49 | K22: =MINA(I22:J22) -> 53.53 | L22: =$D$2 | M22: =K22/(1-L22) -> 53.53 | N22: =IF(I22=K22,"UPS",IF(J22=K22,"FedEx",IF(#REF!=K22,"TNT",0))) -> UPS | P22: 8.5 | Q22: =VLOOKUP($P22, UPS!$J$10:$P$106,((VLOOKUP($E$10,Areas!$B$4:$D$200,2,FALSE))+1),FALSE) -> 56.98 | R22: =VLOOKUP($P22, FedEx!$K$10:$R$96,((VLOOKUP($E$10,Areas!$B$4:$D$200,3,FALSE))+1),FALSE) -> 103.32 | S22: =MINA(Q22:R22) -> 56.98 | T22: =$D$2 | U22: =S22/(1-T22) -> 56.98 | V22: =IF(Q22=S22,"UPS",IF(R22=S22,"FedEx",IF(#REF!=S22,"TNT",0))) -> UPS
C23: 5.5 | D23: =M16+(M16*$D$3) -> 41.99 | E23: =U16+(U16*$D$3) -> 44.67 | H23: 9 | I23: =VLOOKUP($H23,UPS!$B$10:$H$106,((VLOOKUP($E$10,Areas!$B$4:$D$200,2,FALSE))+1),FALSE) -> 55.38 | J23: =VLOOKUP($H23,FedEx!$B$10:$I$96,((VLOOKUP($E$10,Areas!$B$4:$D$200,3,FALSE))+1),FALSE) -> 117.21 | K23: =MINA(I23:J23) -> 55.38 | L23: =$D$2 | M23: =K23/(1-L23) -> 55.38 | N23: =IF(I23=K23,"UPS",IF(J23=K23,"FedEx",IF(#REF!=K23,"TNT",0))) -> UPS | P23: 9 | Q23: =VLOOKUP($P23, UPS!$J$10:$P$106,((VLOOKUP($E$10,Areas!$B$4:$D$200,2,FALSE))+1),FALSE) -> 58.93 | R23: =VLOOKUP($P23, FedEx!$K$10:$R$96,((VLOOKUP($E$10,Areas!$B$4:$D$200,3,FALSE))+1),FALSE) -> 106.68 | S23: =MINA(Q23:R23) -> 58.93 | T23: =$D$2 | U23: =S23/(1-T23) -> 58.93 | V23: =IF(Q23=S23,"UPS",IF(R23=S23,"FedEx",IF(#REF!=S23,"TNT",0))) -> UPS
C24: 6 | D24: =M17+(M17*$D$3) -> 44.07 | E24: =U17+(U17*$D$3) -> 46.88 | H24: 9.5 | I24: =VLOOKUP($H24,UPS!$B$10:$H$106,((VLOOKUP($E$10,Areas!$B$4:$D$200,2,FALSE))+1),FALSE) -> 57.12 | J24: =VLOOKUP($H24,FedEx!$B$10:$I$96,((VLOOKUP($E$10,Areas!$B$4:$D$200,3,FALSE))+1),FALSE) -> 120.93 | K24: =MINA(I24:J24) -> 57.12 | L24: =$D$2 | M24: =K24/(1-L24) -> 57.12 | N24: =IF(I24=K24,"UPS",IF(J24=K24,"FedEx",IF(#REF!=K24,"TNT",0))) -> UPS | P24: 9.5 | Q24: =VLOOKUP($P24, UPS!$J$10:$P$106,((VLOOKUP($E$10,Areas!$B$4:$D$200,2,FALSE))+1),FALSE) -> 60.78 | R24: =VLOOKUP($P24, FedEx!$K$10:$R$96,((VLOOKUP($E$10,Areas!$B$4:$D$200,3,FALSE))+1),FALSE) -> 110.03 | S24: =MINA(Q24:R24) -> 60.78 | T24: =$D$2 | U24: =S24/(1-T24) -> 60.78 | V24: =IF(Q24=S24,"UPS",IF(R24=S24,"FedEx",IF(#REF!=S24,"TNT",0))) -> UPS
... C68: 28 | D68: =M61+(M61*$D$3) -> 127.1 | E68: =U61+(U61*$D$3) -> 135.23 | H68: 31.5 | I68: =VLOOKUP($H68,UPS!$B$10:$H$106,((VLOOKUP($E$10,Areas!$B$4:$D$200,2,FALSE))+1),FALSE) -> 142 | J68: =VLOOKUP($H68,FedEx!$B$10:$I$96,((VLOOKUP($E$10,Areas!$B$4:$D$200,3,FALSE))+1),FALSE) -> 259.2 | K68: =MINA(I68:J68) -> 142 | L68: =$D$2 | M68: =K68/(1-L68) -> 142 | N68: =IF(I68=K68,"UPS",IF(J68=K68,"FedEx",IF(#REF!=K68,"TNT",0))) -> UPS | P68: 31.5 | Q68: =VLOOKUP($P68, UPS!$J$10:$P$106,((VLOOKUP($E$10,Areas!$B$4:$D$200,2,FALSE))+1),FALSE) -> 151.09 | R68: =VLOOKUP($P68, FedEx!$K$10:$R$96,((VLOOKUP($E$10,Areas!$B$4:$D$200,3,FALSE))+1),FALSE) -> 241.28 | S68: =MINA(Q68:R68) -> 151.09 | T68: =$D$2 | U68: =S68/(1-T68) -> 151.09 | V68: =IF(Q68=S68,"UPS",IF(R68=S68,"FedEx",IF(#REF!=S68,"TNT",0))) -> UPS
C69: 28.5 | D69: =M62+(M62*$D$3) -> 129.1 | E69: =U62+(U62*$D$3) -> 137.35 | H69: + 1 kg | I69: =VLOOKUP($H69,UPS!$B$10:$H$106,((VLOOKUP($E$10,Areas!$B$4:$D$200,2,FALSE))+1),FALSE) -> #N/A | J69: =VLOOKUP($H69,FedEx!$B$10:$I$96,((VLOOKUP($E$10,Areas!$B$4:$D$200,3,FALSE))+1),FALSE) -> #N/A | P69: + 1 kg | Q69: =VLOOKUP($P69, UPS!$J$10:$P$106,((VLOOKUP($E$10,Areas!$B$4:$D$200,2,FALSE))+1),FALSE) -> #N/A | R69: =VLOOKUP($P69, FedEx!$K$10:$R$96,((VLOOKUP($E$10,Areas!$B$4:$D$200,3,FALSE))+1),FALSE) -> #N/A
C70: 29 | D70: =M63+(M63*$D$3) -> 131.34 | E70: =U63+(U63*$D$3) -> 139.74
C71: 29.5 | D71: =M64+(M64*$D$3) -> 133.46 | E71: =U64+(U64*$D$3) -> 141.96
C72: 30 | D72: =M65+(M65*$D$3) -> 135.66 | E72: =U65+(U65*$D$3) -> 144.34
C73: 30.5 | D73: =M66+(M66*$D$3) -> 137.83 | E73: =U66+(U66*$D$3) -> 146.63
C74: 31 | D74: =M67+(M67*$D$3) -> 139.87 | E74: =U67+(U67*$D$3) -> 148.81
C75: 31.5 | D75: =M68+(M68*$D$3) -> 142 | E75: =U68+(U68*$D$3) -> 151.09

Sheet Costs
C3: Country: | D3: Colombia
C5: STANDARD | I5: CONNECT PLUS | O5: EXPRESS
B6: Fuel | E6: Best Price | F6: Courier | H6: Fuel | K6: Best Price | L6: Courier | N6: Fuel | Q6: Best Price | R6: Courier
I7: Standard | J7: Connect
N8: Sobre | O8: =(VLOOKUP($N8, UPS!$J$4:$P$9,((VLOOKUP($D$3,Areas!$B$4:$D$200,2,FALSE))+1),FALSE))*(1+$O$6) -> 15.89 | P8: =(VLOOKUP($N8, FedEx!$K$4:$R$9,((VLOOKUP($D$3,Areas!$B$4:$D$200,3,FALSE))+1),FALSE))*(1+$P$6) -> 28.03 | Q8: =MINA(O8:P8) -> 15.89 | R8: =IF(O8=Q8,"UPS",IF(P8=Q8,"FedEx",IF(#REF!=Q8,"DHL",0))) -> UPS
N9: 0.5 | O9: =(VLOOKUP($N9, UPS!$J$4:$P$9,((VLOOKUP($D$3,Areas!$B$4:$D$200,2,FALSE))+1),FALSE))*(1+$O$6) -> 16.77 | P9: =(VLOOKUP($N9, FedEx!$K$4:$R$9,((VLOOKUP($D$3,Areas!$B$4:$D$200,3,FALSE))+1),FALSE))*(1+$P$6) -> 22.43 | Q9: =MINA(O9:P9) -> 16.77 | R9: =IF(O9=Q9,"UPS",IF(P9=Q9,"FedEx",IF(#REF!=Q9,"DHL",0))) -> UPS
N10: 1 | O10: =(VLOOKUP($N10, UPS!$J$4:$P$9,((VLOOKUP($D$3,Areas!$B$4:$D$200,2,FALSE))+1),FALSE))*(1+$O$6) -> 19.65 | P10: =(VLOOKUP($N10, FedEx!$K$4:$R$9,((VLOOKUP($D$3,Areas!$B$4:$D$200,3,FALSE))+1),FALSE))*(1+$P$6) -> 27.97 | Q10: =MINA(O10:P10) -> 19.65 | R10: =IF(O10=Q10,"UPS",IF(P10=Q10,"FedEx",IF(#REF!=Q10,"DHL",0))) -> UPS
N11: 1.5 | O11: =(VLOOKUP($N11, UPS!$J$4:$P$9,((VLOOKUP($D$3,Areas!$B$4:$D$200,2,FALSE))+1),FALSE))*(1+$O$6) -> 23.57 | P11: =(VLOOKUP($N11, FedEx!$K$4:$R$9,((VLOOKUP($D$3,Areas!$B$4:$D$200,3,FALSE))+1),FALSE))*(1+$P$6) -> 33.49 | Q11: =MINA(O11:P11) -> 23.57 | R11: =IF(O11=Q11,"UPS",IF(P11=Q11,"FedEx",IF(#REF!=Q11,"DHL",0))) -> UPS
N12: 2 | O12: =(VLOOKUP($N12, UPS!$J$4:$P$9,((VLOOKUP($D$3,Areas!$B$4:$D$200,2,FALSE))+1),FALSE))*(1+$O$6) -> 27.89 | P12: =(VLOOKUP($N12, FedEx!$K$4:$R$9,((VLOOKUP($D$3,Areas!$B$4:$D$200,3,FALSE))+1),FALSE))*(1+$P$6) -> 39.01 | Q12: =MINA(O12:P12) -> 27.89 | R12: =IF(O12=Q12,"UPS",IF(P12=Q12,"FedEx",IF(#REF!=Q12,"DHL",0))) -> UPS
N13: 2.5 | O13: =(VLOOKUP($N13, UPS!$J$4:$P$9,((VLOOKUP($D$3,Areas!$B$4:$D$200,2,FALSE))+1),FALSE))*(1+$O$6) -> 31.08 | P13: =(VLOOKUP($N13, FedEx!$K$4:$R$9,((VLOOKUP($D$3,Areas!$B$4:$D$200,3,FALSE))+1),FALSE))*(1+$P$6) -> 44.53 | Q13: =MINA(O13:P13) -> 31.08 | R13: =IF(O13=Q13,"UPS",IF(P13=Q13,"FedEx",IF(#REF!=Q13,"DHL",0))) -> UPS
B14: 0.5 | C14: =(VLOOKUP($B14,UPS!$B$10:$H$106,((VLOOKUP($D$3,Areas!$B$4:$D$200,2,FALSE))+1),FALSE))*(1+$C$6) -> 18.02 | D14: =(VLOOKUP($B14,FedEx!$B$10:$I$96,((VLOOKUP($D$3,Areas!$B$4:$D$200,3,FALSE))+1),FALSE))*(1+$D$6) -> 35.19 | E14: =MINA(C14:D14) -> 18.02 | F14: =IF(C14=E14,"UPS",IF(D14=E14,"FedEx",IF(#REF!=E14,"TNT",0))) -> UPS | H14: 0.5 | I14: =E14 -> 18.02 | J14: =(VLOOKUP($H14,FedEx!$T$1:$Y$96,((VLOOKUP($D$3,Areas!$B$4:$E$200,4,FALSE))+1),FALSE))*(1+$J$6) -> 38.22 | K14: =MINA(I14:J14) -> 18.02 | L14: =IF(I14=K14,F14,IF(J14=K14,"Connect")) -> UPS | N14: 0.5 | O14: =(VLOOKUP($N14, UPS!$J$10:$P$106,((VLOOKUP($D$3,Areas!$B$4:$D$200,2,FALSE))+1),FALSE))*(1+$O$6) -> 19.2 | P14: =(VLOOKUP($N14, FedEx!$K$10:$R$96,((VLOOKUP($D$3,Areas!$B$4:$D$200,3,FALSE))+1),FALSE))*(1+$P$6) -> 32.03 | Q14: =MINA(O14:P14) -> 19.2 | R14: =IF(O14=Q14,"UPS",IF(P14=Q14,"FedEx",IF(#REF!=Q14,"DHL",0))) -> UPS
B15: 1 | C15: =(VLOOKUP($B15,UPS!$B$10:$H$106,((VLOOKUP($D$3,Areas!$B$4:$D$200,2,FALSE))+1),FALSE))*(1+$C$6) -> 21.03 | D15: =(VLOOKUP($B15,FedEx!$B$10:$I$96,((VLOOKUP($D$3,Areas!$B$4:$D$200,3,FALSE))+1),FALSE))*(1+$D$6) -> 39.52 | E15: =MINA(C15:D15) -> 21.03 | F15: =IF(C15=E15,"UPS",IF(D15=E15,"FedEx",IF(#REF!=E15,"TNT",0))) -> UPS | H15: 1 | I15: =E15 -> 21.03 | J15: =(VLOOKUP($H15,FedEx!$T$1:$Y$96,((VLOOKUP($D$3,Areas!$B$4:$E$200,4,FALSE))+1),FALSE))*(1+$J$6) -> 38.22 | K15: =MINA(I15:J15) -> 21.03 | L15: =IF(I15=K15,F15,IF(J15=K15,"Connect")) -> UPS | N15: 1 | O15: =(VLOOKUP($N15, UPS!$J$10:$P$106,((VLOOKUP($D$3,Areas!$B$4:$D$200,2,FALSE))+1),FALSE))*(1+$O$6) -> 22.35 | P15: =(VLOOKUP($N15, FedEx!$K$10:$R$96,((VLOOKUP($D$3,Areas!$B$4:$D$200,3,FALSE))+1),FALSE))*(1+$P$6) -> 36.07 | Q15: =MINA(O15:P15) -> 22.35 | R15: =IF(O15=Q15,"UPS",IF(P15=Q15,"FedEx",IF(#REF!=Q15,"DHL",0))) -> UPS
B16: 1.5 | C16: =(VLOOKUP($B16,UPS!$B$10:$H$106,((VLOOKUP($D$3,Areas!$B$4:$D$200,2,FALSE))+1),FALSE))*(1+$C$6) -> 24.04 | D16: =(VLOOKUP($B16,FedEx!$B$10:$I$96,((VLOOKUP($D$3,Areas!$B$4:$D$200,3,FALSE))+1),FALSE))*(1+$D$6) -> 43.85 | E16: =MINA(C16:D16) -> 24.04 | F16: =IF(C16=E16,"UPS",IF(D16=E16,"FedEx",IF(#REF!=E16,"TNT",0))) -> UPS | H16: 1.5 | I16: =E16 -> 24.04 | J16: =(VLOOKUP($H16,FedEx!$T$1:$Y$96,((VLOOKUP($D$3,Areas!$B$4:$E$200,4,FALSE))+1),FALSE))*(1+$J$6) -> 38.22 | K16: =MINA(I16:J16) -> 24.04 | L16: =IF(I16=K16,F16,IF(J16=K16,"Connect")) -> UPS | N16: 1.5 | O16: =(VLOOKUP($N16, UPS!$J$10:$P$106,((VLOOKUP($D$3,Areas!$B$4:$D$200,2,FALSE))+1),FALSE))*(1+$O$6) -> 25.58 | P16: =(VLOOKUP($N16, FedEx!$K$10:$R$96,((VLOOKUP($D$3,Areas!$B$4:$D$200,3,FALSE))+1),FALSE))*(1+$P$6) -> 40.11 | Q16: =MINA(O16:P16) -> 25.58 | R16: =IF(O16=Q16,"UPS",IF(P16=Q16,"FedEx",IF(#REF!=Q16,"DHL",0))) -> UPS
B17: 2 | C17: =(VLOOKUP($B17,UPS!$B$10:$H$106,((VLOOKUP($D$3,Areas!$B$4:$D$200,2,FALSE))+1),FALSE))*(1+$C$6) -> 27.27 | D17: =(VLOOKUP($B17,FedEx!$B$10:$I$96,((VLOOKUP($D$3,Areas!$B$4:$D$200,3,FALSE))+1),FALSE))*(1+$D$6) -> 48.18 | E17: =MINA(C17:D17) -> 27.27 | F17: =IF(C17=E17,"UPS",IF(D17=E17,"FedEx",IF(#REF!=E17,"TNT",0))) -> UPS | H17: 2 | I17: =E17 -> 27.27 | J17: =(VLOOKUP($H17,FedEx!$T$1:$Y$96,((VLOOKUP($D$3,Areas!$B$4:$E$200,4,FALSE))+1),FALSE))*(1+$J$6) -> 38.22 | K17: =MINA(I17:J17) -> 27.27 | L17: =IF(I17=K17,F17,IF(J17=K17,"Connect")) -> UPS | N17: 2 | O17: =(VLOOKUP($N17, UPS!$J$10:$P$106,((VLOOKUP($D$3,Areas!$B$4:$D$200,2,FALSE))+1),FALSE))*(1+$O$6) -> 29.02 | P17: =(VLOOKUP($N17, FedEx!$K$10:$R$96,((VLOOKUP($D$3,Areas!$B$4:$D$200,3,FALSE))+1),FALSE))*(1+$P$6) -> 44.14 | Q17: =MINA(O17:P17) -> 29.02 | R17: =IF(O17=Q17,"UPS",IF(P17=Q17,"FedEx",IF(#REF!=Q17,"DHL",0))) -> UPS
B18: 2.5 | C18: =(VLOOKUP($B18,UPS!$B$10:$H$106,((VLOOKUP($D$3,Areas!$B$4:$D$200,2,FALSE))+1),FALSE))*(1+$C$6) -> 30.02 | D18: =(VLOOKUP($B18,FedEx!$B$10:$I$96,((VLOOKUP($D$3,Areas!$B$4:$D$200,3,FALSE))+1),FALSE))*(1+$D$6) -> 52.51 | E18: =MINA(C18:D18) -> 30.02 | F18: =IF(C18=E18,"UPS",IF(D18=E18,"FedEx",IF(#REF!=E18,"TNT",0))) -> UPS | H18: 2.5 | I18: =E18 -> 30.02 | J18: =(VLOOKUP($H18,FedEx!$T$1:$Y$96,((VLOOKUP($D$3,Areas!$B$4:$E$200,4,FALSE))+1),FALSE))*(1+$J$6) -> 38.22 | K18: =MINA(I18:J18) -> 30.02 | L18: =IF(I18=K18,F18,IF(J18=K18,"Connect")) -> UPS | N18: 2.5 | O18: =(VLOOKUP($N18, UPS!$J$10:$P$106,((VLOOKUP($D$3,Areas!$B$4:$D$200,2,FALSE))+1),FALSE))*(1+$O$6) -> 31.94 | P18: =(VLOOKUP($N18, FedEx!$K$10:$R$96,((VLOOKUP($D$3,Areas!$B$4:$D$200,3,FALSE))+1),FALSE))*(1+$P$6) -> 48.18 | Q18: =MINA(O18:P18) -> 31.94 | R18: =IF(O18=Q18,"UPS",IF(P18=Q18,"FedEx",IF(#REF!=Q18,"DHL",0))) -> UPS
B19: 3 | C19: =(VLOOKUP($B19,UPS!$B$10:$H$106,((VLOOKUP($D$3,Areas!$B$4:$D$200,2,FALSE))+1),FALSE))*(1+$C$6) -> 31.79 | D19: =(VLOOKUP($B19,FedEx!$B$10:$I$96,((VLOOKUP($D$3,Areas!$B$4:$D$200,3,FALSE))+1),FALSE))*(1+$D$6) -> 57.04 | E19: =MINA(C19:D19) -> 31.79 | F19: =IF(C19=E19,"UPS",IF(D19=E19,"FedEx",IF(#REF!=E19,"TNT",0))) -> UPS | H19: 3 | I19: =E19 -> 31.79 | J19: =(VLOOKUP($H19,FedEx!$T$1:$Y$96,((VLOOKUP($D$3,Areas!$B$4:$E$200,4,FALSE))+1),FALSE))*(1+$J$6) -> 69.02 | K19: =MINA(I19:J19) -> 31.79 | L19: =IF(I19=K19,F19,IF(J19=K19,"Connect")) -> UPS | N19: 3 | O19: =(VLOOKUP($N19, UPS!$J$10:$P$106,((VLOOKUP($D$3,Areas!$B$4:$D$200,2,FALSE))+1),FALSE))*(1+$O$6) -> 33.83 | P19: =(VLOOKUP($N19, FedEx!$K$10:$R$96,((VLOOKUP($D$3,Areas!$B$4:$D$200,3,FALSE))+1),FALSE))*(1+$P$6) -> 52.19 | Q19: =MINA(O19:P19) -> 33.83 | R19: =IF(O19=Q19,"UPS",IF(P19=Q19,"FedEx",IF(#REF!=Q19,"DHL",0))) -> UPS
B20: 3.5 | C20: =(VLOOKUP($B20,UPS!$B$10:$H$106,((VLOOKUP($D$3,Areas!$B$4:$D$200,2,FALSE))+1),FALSE))*(1+$C$6) -> 33.75 | D20: =(VLOOKUP($B20,FedEx!$B$10:$I$96,((VLOOKUP($D$3,Areas!$B$4:$D$200,3,FALSE))+1),FALSE))*(1+$D$6) -> 61.58 | E20: =MINA(C20:D20) -> 33.75 | F20: =IF(C20=E20,"UPS",IF(D20=E20,"FedEx",IF(#REF!=E20,"TNT",0))) -> UPS | H20: 3.5 | I20: =E20 -> 33.75 | J20: =(VLOOKUP($H20,FedEx!$T$1:$Y$96,((VLOOKUP($D$3,Areas!$B$4:$E$200,4,FALSE))+1),FALSE))*(1+$J$6) -> 69.02 | K20: =MINA(I20:J20) -> 33.75 | L20: =IF(I20=K20,F20,IF(J20=K20,"Connect")) -> UPS | N20: 3.5 | O20: =(VLOOKUP($N20, UPS!$J$10:$P$106,((VLOOKUP($D$3,Areas!$B$4:$D$200,2,FALSE))+1),FALSE))*(1+$O$6) -> 35.93 | P20: =(VLOOKUP($N20, FedEx!$K$10:$R$96,((VLOOKUP($D$3,Areas!$B$4:$D$200,3,FALSE))+1),FALSE))*(1+$P$6) -> 56.21 | Q20: =MINA(O20:P20) -> 35.93 | R20: =IF(O20=Q20,"UPS",IF(P20=Q20,"FedEx",IF(#REF!=Q20,"DHL",0))) -> UPS
B21: 4 | C21: =(VLOOKUP($B21,UPS!$B$10:$H$106,((VLOOKUP($D$3,Areas!$B$4:$D$200,2,FALSE))+1),FALSE))*(1+$C$6) -> 35.74 | D21: =(VLOOKUP($B21,FedEx!$B$10:$I$96,((VLOOKUP($D$3,Areas!$B$4:$D$200,3,FALSE))+1),FALSE))*(1+$D$6) -> 66.12 | E21: =MINA(C21:D21) -> 35.74 | F21: =IF(C21=E21,"UPS",IF(D21=E21,"FedEx",IF(#REF!=E21,"TNT",0))) -> UPS | H21: 4 | I21: =E21 -> 35.74 | J21: =(VLOOKUP($H21,FedEx!$T$1:$Y$96,((VLOOKUP($D$3,Areas!$B$4:$E$200,4,FALSE))+1),FALSE))*(1+$J$6) -> 69.02 | K21: =MINA(I21:J21) -> 35.74 | L21: =IF(I21=K21,F21,IF(J21=K21,"Connect")) -> UPS | N21: 4 | O21: =(VLOOKUP($N21, UPS!$J$10:$P$106,((VLOOKUP($D$3,Areas!$B$4:$D$200,2,FALSE))+1),FALSE))*(1+$O$6) -> 38.03 | P21: =(VLOOKUP($N21, FedEx!$K$10:$R$96,((VLOOKUP($D$3,Areas!$B$4:$D$200,3,FALSE))+1),FALSE))*(1+$P$6) -> 60.22 | Q21: =MINA(O21:P21) -> 38.03 | R21: =IF(O21=Q21,"UPS",IF(P21=Q21,"FedEx",IF(#REF!=Q21,"DHL",0))) -> UPS
B22: 4.5 | C22: =(VLOOKUP($B22,UPS!$B$10:$H$106,((VLOOKUP($D$3,Areas!$B$4:$D$200,2,FALSE))+1),FALSE))*(1+$C$6) -> 37.86 | D22: =(VLOOKUP($B22,FedEx!$B$10:$I$96,((VLOOKUP($D$3,Areas!$B$4:$D$200,3,FALSE))+1),FALSE))*(1+$D$6) -> 70.65 | E22: =MINA(C22:D22) -> 37.86 | F22: =IF(C22=E22,"UPS",IF(D22=E22,"FedEx",IF(#REF!=E22,"TNT",0))) -> UPS | H22: 4.5 | I22: =E22 -> 37.86 | J22: =(VLOOKUP($H22,FedEx!$T$1:$Y$96,((VLOOKUP($D$3,Areas!$B$4:$E$200,4,FALSE))+1),FALSE))*(1+$J$6) -> 69.02 | K22: =MINA(I22:J22) -> 37.86 | L22: =IF(I22=K22,F22,IF(J22=K22,"Connect")) -> UPS | N22: 4.5 | O22: =(VLOOKUP($N22, UPS!$J$10:$P$106,((VLOOKUP($D$3,Areas!$B$4:$D$200,2,FALSE))+1),FALSE))*(1+$O$6) -> 40.27 | P22: =(VLOOKUP($N22, FedEx!$K$10:$R$96,((VLOOKUP($D$3,Areas!$B$4:$D$200,3,FALSE))+1),FALSE))*(1+$P$6) -> 64.24 | Q22: =MINA(O22:P22) -> 40.27 | R22: =IF(O22=Q22,"UPS",IF(P22=Q22,"FedEx",IF(#REF!=Q22,"DHL",0))) -> UPS
B23: 5 | C23: =(VLOOKUP($B23,UPS!$B$10:$H$106,((VLOOKUP($D$3,Areas!$B$4:$D$200,2,FALSE))+1),FALSE))*(1+$C$6) -> 40.07 | D23: =(VLOOKUP($B23,FedEx!$B$10:$I$96,((VLOOKUP($D$3,Areas!$B$4:$D$200,3,FALSE))+1),FALSE))*(1+$D$6) -> 75.19 | E23: =MINA(C23:D23) -> 40.07 | F23: =IF(C23=E23,"UPS",IF(D23=E23,"FedEx",IF(#REF!=E23,"TNT",0))) -> UPS | H23: 5 | I23: =E23 -> 40.07 | J23: =(VLOOKUP($H23,FedEx!$T$1:$Y$96,((VLOOKUP($D$3,Areas!$B$4:$E$200,4,FALSE))+1),FALSE))*(1+$J$6) -> 69.02 | K23: =MINA(I23:J23) -> 40.07 | L23: =IF(I23=K23,F23,IF(J23=K23,"Connect")) -> UPS | N23: 5 | O23: =(VLOOKUP($N23, UPS!$J$10:$P$106,((VLOOKUP($D$3,Areas!$B$4:$D$200,2,FALSE))+1),FALSE))*(1+$O$6) -> 42.64 | P23: =(VLOOKUP($N23, FedEx!$K$10:$R$96,((VLOOKUP($D$3,Areas!$B$4:$D$200,3,FALSE))+1),FALSE))*(1+$P$6) -> 68.25 | Q23: =MINA(O23:P23) -> 42.64 | R23: =IF(O23=Q23,"UPS",IF(P23=Q23,"FedEx",IF(#REF!=Q23,"DHL",0))) -> UPS
B24: 5.5 | C24: =(VLOOKUP($B24,UPS!$B$10:$H$106,((VLOOKUP($D$3,Areas!$B$4:$D$200,2,FALSE))+1),FALSE))*(1+$C$6) -> 41.99 | D24: =(VLOOKUP($B24,FedEx!$B$10:$I$96,((VLOOKUP($D$3,Areas!$B$4:$D$200,3,FALSE))+1),FALSE))*(1+$D$6) -> 78.35 | E24: =MINA(C24:D24) -> 41.99 | F24: =IF(C24=E24,"UPS",IF(D24=E24,"FedEx",IF(#REF!=E24,"TNT",0))) -> UPS | H24: 5.5 | I24: =E24 -> 41.99 | J24: =(VLOOKUP($H24,FedEx!$T$1:$Y$96,((VLOOKUP($D$3,Areas!$B$4:$E$200,4,FALSE))+1),FALSE))*(1+$J$6) -> 97.62 | K24: =MINA(I24:J24) -> 41.99 | L24: =IF(I24=K24,F24,IF(J24=K24,"Connect")) -> UPS | N24: 5.5 | O24: =(VLOOKUP($N24, UPS!$J$10:$P$106,((VLOOKUP($D$3,Areas!$B$4:$D$200,2,FALSE))+1),FALSE))*(1+$O$6) -> 44.67 | P24: =(VLOOKUP($N24, FedEx!$K$10:$R$96,((VLOOKUP($D$3,Areas!$B$4:$D$200,3,FALSE))+1),FALSE))*(1+$P$6) -> 71.2 | Q24: =MINA(O24:P24) -> 44.67 | R24: =IF(O24=Q24,"UPS",IF(P24=Q24,"FedEx",IF(#REF!=Q24,"DHL",0))) -> UPS
B25: 6 | C25: =(VLOOKUP($B25,UPS!$B$10:$H$106,((VLOOKUP($D$3,Areas!$B$4:$D$200,2,FALSE))+1),FALSE))*(1+$C$6) -> 44.07 | D25: =(VLOOKUP($B25,FedEx!$B$10:$I$96,((VLOOKUP($D$3,Areas!$B$4:$D$200,3,FALSE))+1),FALSE))*(1+$D$6) -> 81.51 | E25: =MINA(C25:D25) -> 44.07 | F25: =IF(C25=E25,"UPS",IF(D25=E25,"FedEx",IF(#REF!=E25,"TNT",0))) -> UPS | H25: 6 | I25: =E25 -> 44.07 | J25: =(VLOOKUP($H25,FedEx!$T$1:$Y$96,((VLOOKUP($D$3,Areas!$B$4:$E$200,4,FALSE))+1),FALSE))*(1+$J$6) -> 97.62 | K25: =MINA(I25:J25) -> 44.07 | L25: =IF(I25=K25,F25,IF(J25=K25,"Connect")) -> UPS | N25: 6 | O25: =(VLOOKUP($N25, UPS!$J$10:$P$106,((VLOOKUP($D$3,Areas!$B$4:$D$200,2,FALSE))+1),FALSE))*(1+$O$6) -> 46.88 | P25: =(VLOOKUP($N25, FedEx!$K$10:$R$96,((VLOOKUP($D$3,Areas!$B$4:$D$200,3,FALSE))+1),FALSE))*(1+$P$6) -> 74.15 | Q25: =MINA(O25:P25) -> 46.88 | R25: =IF(O25=Q25,"UPS",IF(P25=Q25,"FedEx",IF(#REF!=Q25,"DHL",0))) -> UPS
... B76: 31.5 | C76: =(VLOOKUP($B76,UPS!$B$10:$H$106,((VLOOKUP($D$3,Areas!$B$4:$D$200,2,FALSE))+1),FALSE))*(1+$C$6) -> 142 | D76: =(VLOOKUP($B76,FedEx!$B$10:$I$96,((VLOOKUP($D$3,Areas!$B$4:$D$200,3,FALSE))+1),FALSE))*(1+$D$6) -> 237.12 | E76: =MINA(C76:D76) -> 142 | F76: =IF(C76=E76,"UPS",IF(D76=E76,"FedEx",IF(#REF!=E76,"TNT",0))) -> UPS | H76: 31.5 | I76: =E76 -> 142 | J76: =(VLOOKUP($H76,FedEx!$T$1:$Y$96,((VLOOKUP($D$3,Areas!$B$4:$E$200,4,FALSE))+1),FALSE))*(1+$J$6) -> 246.4 | K76: =MINA(I76:J76) -> 142 | L76: =IF(I76=K76,F76,IF(J76=K76,"Connect")) -> UPS | N76: 31.5 | O76: =(VLOOKUP($N76, UPS!$J$10:$P$106,((VLOOKUP($D$3,Areas!$B$4:$D$200,2,FALSE))+1),FALSE))*(1+$O$6) -> 151.09 | P76: =(VLOOKUP($N76, FedEx!$K$10:$R$96,((VLOOKUP($D$3,Areas!$B$4:$D$200,3,FALSE))+1),FALSE))*(1+$P$6) -> 223.04 | Q76: =MINA(O76:P76) -> 151.09 | R76: =IF(O76=Q76,"UPS",IF(P76=Q76,"FedEx",IF(#REF!=Q76,"DHL",0))) -> UPS
B77: 32 - 44 | C77: =(VLOOKUP($B77,UPS!$B$10:$H$106,((VLOOKUP($D$3,Areas!$B$4:$D$200,2,FALSE))+1),FALSE))*(1+$C$6) -> 4.52 | D77: =(VLOOKUP($B77,FedEx!$B$10:$I$96,((VLOOKUP($D$3,Areas!$B$4:$D$200,3,FALSE))+1),FALSE))*(1+$D$6) -> 7.41 | E77: =MINA(C77:D77) -> 4.52 | F77: =IF(C77=E77,"UPS",IF(D77=E77,"FedEx",IF(#REF!=E77,"TNT",0))) -> UPS | H77: 32 - 44 | I77: =E77 -> 4.52 | J77: =(VLOOKUP($H77,FedEx!$T$1:$Y$96,((VLOOKUP($D$3,Areas!$B$4:$E$200,4,FALSE))+1),FALSE))*(1+$J$6) -> 7.7 | K77: =MINA(I77:J77) -> 4.52 | L77: =IF(I77=K77,F77,IF(J77=K77,"Connect")) -> UPS | N77: 32 - 44 | O77: =(VLOOKUP($N77, UPS!$J$10:$P$106,((VLOOKUP($D$3,Areas!$B$4:$D$200,2,FALSE))+1),FALSE))*(1+$O$6) -> 4.81 | P77: =(VLOOKUP($N77, FedEx!$K$10:$R$96,((VLOOKUP($D$3,Areas!$B$4:$D$200,3,FALSE))+1),FALSE))*(1+$P$6) -> 6.97 | Q77: =MINA(O77:P77) -> 4.81 | R77: =IF(O77=Q77,"UPS",IF(P77=Q77,"FedEx",IF(#REF!=Q77,"DHL",0))) -> UPS
B78: 45 - 67 | C78: =(VLOOKUP($B78,UPS!$B$10:$H$106,((VLOOKUP($D$3,Areas!$B$4:$D$200,2,FALSE))+1),FALSE))*(1+$C$6) -> 4.52 | D78: =(VLOOKUP($B78,FedEx!$B$10:$I$96,((VLOOKUP($D$3,Areas!$B$4:$D$200,3,FALSE))+1),FALSE))*(1+$D$6) -> 6.87 | E78: =MINA(C78:D78) -> 4.52 | F78: =IF(C78=E78,"UPS",IF(D78=E78,"FedEx",IF(#REF!=E78,"TNT",0))) -> UPS | H78: 45 - 67 | I78: =E78 -> 4.52 | J78: =(VLOOKUP($H78,FedEx!$T$1:$Y$96,((VLOOKUP($D$3,Areas!$B$4:$E$200,4,FALSE))+1),FALSE))*(1+$J$6) -> 7.7 | K78: =MINA(I78:J78) -> 4.52 | L78: =IF(I78=K78,F78,IF(J78=K78,"Connect")) -> UPS | N78: 45 - 67 | O78: =(VLOOKUP($N78, UPS!$J$10:$P$106,((VLOOKUP($D$3,Areas!$B$4:$D$200,2,FALSE))+1),FALSE))*(1+$O$6) -> 4.81 | P78: =(VLOOKUP($N78, FedEx!$K$10:$R$96,((VLOOKUP($D$3,Areas!$B$4:$D$200,3,FALSE))+1),FALSE))*(1+$P$6) -> 6.41 | Q78: =MINA(O78:P78) -> 4.81 | R78: =IF(O78=Q78,"UPS",IF(P78=Q78,"FedEx",IF(#REF!=Q78,"DHL",0))) -> UPS
B79: 68 - 70 | C79: =(VLOOKUP($B79,UPS!$B$10:$H$106,((VLOOKUP($D$3,Areas!$B$4:$D$200,2,FALSE))+1),FALSE))*(1+$C$6) -> 4.52 | D79: =(VLOOKUP($B79,FedEx!$B$10:$I$96,((VLOOKUP($D$3,Areas!$B$4:$D$200,3,FALSE))+1),FALSE))*(1+$D$6) -> 5.95 | E79: =MINA(C79:D79) -> 4.52 | F79: =IF(C79=E79,"UPS",IF(D79=E79,"FedEx",IF(#REF!=E79,"TNT",0))) -> UPS | H79: 68 - 70 | I79: =E79 -> 4.52 | J79: =(VLOOKUP($H79,FedEx!$T$1:$Y$96,((VLOOKUP($D$3,Areas!$B$4:$E$200,4,FALSE))+1),FALSE))*(1+$J$6) -> 7.7 | K79: =MINA(I79:J79) -> 4.52 | L79: =IF(I79=K79,F79,IF(J79=K79,"Connect")) -> UPS | N79: 68 - 70 | O79: =(VLOOKUP($N79, UPS!$J$10:$P$106,((VLOOKUP($D$3,Areas!$B$4:$D$200,2,FALSE))+1),FALSE))*(1+$O$6) -> 4.81 | P79: =(VLOOKUP($N79, FedEx!$K$10:$R$96,((VLOOKUP($D$3,Areas!$B$4:$D$200,3,FALSE))+1),FALSE))*(1+$P$6) -> 6.41 | Q79: =MINA(O79:P79) -> 4.81 | R79: =IF(O79=Q79,"UPS",IF(P79=Q79,"FedEx",IF(#REF!=Q79,"DHL",0))) -> UPS
B80: 71 - 99 | C80: =(VLOOKUP($B80,UPS!$B$10:$H$106,((VLOOKUP($D$3,Areas!$B$4:$D$200,2,FALSE))+1),FALSE))*(1+$C$6) -> 4.52 | D80: =(VLOOKUP($B80,FedEx!$B$10:$I$96,((VLOOKUP($D$3,Areas!$B$4:$D$200,3,FALSE))+1),FALSE))*(1+$D$6) -> 5.89 | E80: =MINA(C80:D80) -> 4.52 | F80: =IF(C80=E80,"UPS",IF(D80=E80,"FedEx",IF(#REF!=E80,"TNT",0))) -> UPS | H80: 71 - 99 | I80: =E80 -> 4.52 | J80: =(VLOOKUP($H80,FedEx!$T$1:$Y$96,((VLOOKUP($D$3,Areas!$B$4:$E$200,4,FALSE))+1),FALSE))*(1+$J$6) -> 7.7 | K80: =MINA(I80:J80) -> 4.52 | L80: =IF(I80=K80,F80,IF(J80=K80,"Connect")) -> UPS | N80: 71 - 99 | O80: =(VLOOKUP($N80, UPS!$J$10:$P$106,((VLOOKUP($D$3,Areas!$B$4:$D$200,2,FALSE))+1),FALSE))*(1+$O$6) -> 4.81 | P80: =(VLOOKUP($N80, FedEx!$K$10:$R$96,((VLOOKUP($D$3,Areas!$B$4:$D$200,3,FALSE))+1),FALSE))*(1+$P$6) -> 6.34 | Q80: =MINA(O80:P80) -> 4.81 | R80: =IF(O80=Q80,"UPS",IF(P80=Q80,"FedEx",IF(#REF!=Q80,"DHL",0))) -> UPS
B81: 100 - 299 | C81: =(VLOOKUP($B81,UPS!$B$10:$H$106,((VLOOKUP($D$3,Areas!$B$4:$D$200,2,FALSE))+1),FALSE))*(1+$C$6) -> 4.52 | D81: =(VLOOKUP($B81,FedEx!$B$10:$I$96,((VLOOKUP($D$3,Areas!$B$4:$D$200,3,FALSE))+1),FALSE))*(1+$D$6) -> 5.85 | E81: =MINA(C81:D81) -> 4.52 | F81: =IF(C81=E81,"UPS",IF(D81=E81,"FedEx",IF(#REF!=E81,"TNT",0))) -> UPS | H81: 100 - 299 | I81: =E81 -> 4.52 | J81: =(VLOOKUP($H81,FedEx!$T$1:$Y$96,((VLOOKUP($D$3,Areas!$B$4:$E$200,4,FALSE))+1),FALSE))*(1+$J$6) -> 7.7 | K81: =MINA(I81:J81) -> 4.52 | L81: =IF(I81=K81,F81,IF(J81=K81,"Connect")) -> UPS | N81: 100 - 299 | O81: =(VLOOKUP($N81, UPS!$J$10:$P$106,((VLOOKUP($D$3,Areas!$B$4:$D$200,2,FALSE))+1),FALSE))*(1+$O$6) -> 4.81 | P81: =(VLOOKUP($N81, FedEx!$K$10:$R$96,((VLOOKUP($D$3,Areas!$B$4:$D$200,3,FALSE))+1),FALSE))*(1+$P$6) -> 6.34 | Q81: =MINA(O81:P81) -> 4.81 | R81: =IF(O81=Q81,"UPS",IF(P81=Q81,"FedEx",IF(#REF!=Q81,"DHL",0))) -> UPS
B82: 300 - 499 | C82: =(VLOOKUP($B82,UPS!$B$10:$H$106,((VLOOKUP($D$3,Areas!$B$4:$D$200,2,FALSE))+1),FALSE))*(1+$C$6) -> 4.52 | D82: =(VLOOKUP($B82,FedEx!$B$10:$I$96,((VLOOKUP($D$3,Areas!$B$4:$D$200,3,FALSE))+1),FALSE))*(1+$D$6) -> 5.84 | E82: =MINA(C82:D82) -> 4.52 | F82: =IF(C82=E82,"UPS",IF(D82=E82,"FedEx",IF(#REF!=E82,"TNT",0))) -> UPS | H82: 300 - 499 | I82: =E82 -> 4.52 | J82: =(VLOOKUP($H82,FedEx!$T$1:$Y$96,((VLOOKUP($D$3,Areas!$B$4:$E$200,4,FALSE))+1),FALSE))*(1+$J$6) -> 7.7 | K82: =MINA(I82:J82) -> 4.52 | L82: =IF(I82=K82,F82,IF(J82=K82,"Connect")) -> UPS | N82: 300 - 499 | O82: =(VLOOKUP($N82, UPS!$J$10:$P$106,((VLOOKUP($D$3,Areas!$B$4:$D$200,2,FALSE))+1),FALSE))*(1+$O$6) -> 4.81 | P82: =(VLOOKUP($N82, FedEx!$K$10:$R$96,((VLOOKUP($D$3,Areas!$B$4:$D$200,3,FALSE))+1),FALSE))*(1+$P$6) -> 6.33 | Q82: =MINA(O82:P82) -> 4.81 | R82: =IF(O82=Q82,"UPS",IF(P82=Q82,"FedEx",IF(#REF!=Q82,"DHL",0))) -> UPS
B83: 500 - 999 | C83: =(VLOOKUP($B83,UPS!$B$10:$H$106,((VLOOKUP($D$3,Areas!$B$4:$D$200,2,FALSE))+1),FALSE))*(1+$C$6) -> 4.52 | D83: =(VLOOKUP($B83,FedEx!$B$10:$I$96,((VLOOKUP($D$3,Areas!$B$4:$D$200,3,FALSE))+1),FALSE))*(1+$D$6) -> 5.84 | E83: =MINA(C83:D83) -> 4.52 | F83: =IF(C83=E83,"UPS",IF(D83=E83,"FedEx",IF(#REF!=E83,"TNT",0))) -> UPS | H83: 500 - 999 | I83: =E83 -> 4.52 | J83: =(VLOOKUP($H83,FedEx!$T$1:$Y$96,((VLOOKUP($D$3,Areas!$B$4:$E$200,4,FALSE))+1),FALSE))*(1+$J$6) -> 7.7 | K83: =MINA(I83:J83) -> 4.52 | L83: =IF(I83=K83,F83,IF(J83=K83,"Connect")) -> UPS | N83: 500 - 999 | O83: =(VLOOKUP($N83, UPS!$J$10:$P$106,((VLOOKUP($D$3,Areas!$B$4:$D$200,2,FALSE))+1),FALSE))*(1+$O$6) -> 4.81 | P83: =(VLOOKUP($N83, FedEx!$K$10:$R$96,((VLOOKUP($D$3,Areas!$B$4:$D$200,3,FALSE))+1),FALSE))*(1+$P$6) -> 6.33 | Q83: =MINA(O83:P83) -> 4.81 | R83: =IF(O83=Q83,"UPS",IF(P83=Q83,"FedEx",IF(#REF!=Q83,"DHL",0))) -> UPS
B84: +1,000 | C84: =(VLOOKUP($B84,UPS!$B$10:$H$106,((VLOOKUP($D$3,Areas!$B$4:$D$200,2,FALSE))+1),FALSE))*(1+$C$6) -> 4.52 | D84: =(VLOOKUP($B84,FedEx!$B$10:$I$96,((VLOOKUP($D$3,Areas!$B$4:$D$200,3,FALSE))+1),FALSE))*(1+$D$6) -> 5.84 | E84: =MINA(C84:D84) -> 4.52 | F84: =IF(C84=E84,"UPS",IF(D84=E84,"FedEx",IF(#REF!=E84,"TNT",0))) -> UPS | H84: +1,000 | I84: =E84 -> 4.52 | J84: =(VLOOKUP($H84,FedEx!$T$1:$Y$96,((VLOOKUP($D$3,Areas!$B$4:$E$200,4,FALSE))+1),FALSE))*(1+$J$6) -> 7.7 | K84: =MINA(I84:J84) -> 4.52 | L84: =IF(I84=K84,F84,IF(J84=K84,"Connect")) -> UPS | N84: +1,000 | O84: =(VLOOKUP($N84, UPS!$J$10:$P$106,((VLOOKUP($D$3,Areas!$B$4:$D$200,2,FALSE))+1),FALSE))*(1+$O$6) -> 4.81 | P84: =(VLOOKUP($N84, FedEx!$K$10:$R$96,((VLOOKUP($D$3,Areas!$B$4:$D$200,3,FALSE))+1),FALSE))*(1+$P$6) -> 6.33 | Q84: =MINA(O84:P84) -> 4.81 | R84: =IF(O84=Q84,"UPS",IF(P84=Q84,"FedEx",IF(#REF!=Q84,"DHL",0))) -> UPS

Sheet FedEx
C2: Economy | L2: Priority | U2: Connect Plus
C3: Zone 1 | D3: Zone 2 | E3: Zone 3 | F3: Zone 4 | G3: Zone 5 | H3: Zone 6 | I3: Zone 7 | L3: Zone 1 | M3: Zone 2 | N3: Zone 3 | O3: Zone 4 | P3: Zone 5 | Q3: Zone 6 | R3: Zone 7 | U3: Zone 1 | V3: Zone 2 | W3: Zone 3 | X3: Zone 4
K4: Sobre | L4: 18.52 | M4: 28.03 | N4: 32.77 | O4: 36.45 | P4: 33.69 | Q4: 35.86 | R4: 36.45
K5: 0.5 | L5: 14.82 | M5: 22.43 | N5: 26.22 | O5: 30.84 | P5: 30.63 | Q5: 35.86 | R5: 30.84
K6: 1 | L6: 19.6 | M6: 27.97 | N6: 33.84 | O6: 38.96 | P6: 38.15 | Q6: 43.2 | R6: 38.96
K7: 1.5 | L7: 23.86 | M7: 33.49 | N7: 40.81 | O7: 46.8 | P7: 45.42 | Q7: 50.83 | R7: 46.8
K8: 2 | L8: 28.12 | M8: 39.01 | N8: 47.78 | O8: 54.65 | P8: 52.69 | Q8: 58.46 | R8: 54.65
K9: 2.5 | L9: 32.38 | M9: 44.53 | N9: 54.76 | O9: 62.49 | P9: 59.96 | Q9: 66.09 | R9: 62.49
B10: 0.5 | C10: 28.12 | D10: 35.19 | E10: 35.49 | F10: 38.8 | G10: 41.87 | H10: 54.06 | I10: 42.29 | K10: 0.5 | L10: 25.79 | M10: 32.03 | N10: 32.45 | O10: 38.18 | P10: 41.08 | Q10: 53.5 | R10: 38.17 | T10: 0.5 | U10: 38.22 | V10: 48.95 | W10: 53.62 | X10: 62.15 | Z10: =min(C10,L10) -> 25.79 | AA10: =min(D10,M10) -> 32.03 | AB10: =min(E10,N10) -> 32.45 | AC10: =min(F10,O10) -> 38.18 | AD10: =min(G10,P10) -> 41.08 | AE10: =min(H10,Q10) -> 53.5 | AF10: =min(I10,R10) -> 38.17
B11: 1 | C11: 30.34 | D11: 39.52 | E11: 41.3 | F11: 45.01 | G11: 48.47 | H11: 62.05 | I11: 49.02 | K11: 1 | L11: 27.79 | M11: 36.07 | N11: 37.7 | O11: 44.25 | P11: 47.43 | Q11: 61.43 | R11: 44.25 | T11: 1 | U11: 38.22 | V11: 48.95 | W11: 53.62 | X11: 62.15 | Z11: =min(C11,L11) -> 27.79 | AA11: =min(D11,M11) -> 36.07 | AB11: =min(E11,N11) -> 37.7 | AC11: =min(F11,O11) -> 44.25 | AD11: =min(G11,P11) -> 47.43 | AE11: =min(H11,Q11) -> 61.43 | AF11: =min(I11,R11) -> 44.25
B12: 1.5 | C12: 32.56 | D12: 43.85 | E12: 47.11 | F12: 51.23 | G12: 55.07 | H12: 70.04 | I12: 55.74 | K12: 1.5 | L12: 29.78 | M12: 40.11 | N12: 42.94 | O12: 50.32 | P12: 53.78 | Q12: 69.37 | R12: 50.33 | T12: 1.5 | U12: 38.22 | V12: 48.95 | W12: 53.62 | X12: 62.15 | Z12: =min(C12,L12) -> 29.78 | AA12: =min(D12,M12) -> 40.11 | AB12: =min(E12,N12) -> 42.94 | AC12: =min(F12,O12) -> 50.32 | AD12: =min(G12,P12) -> 53.78 | AE12: =min(H12,Q12) -> 69.37 | AF12: =min(I12,R12) -> 50.33
B13: 2 | C13: 34.79 | D13: 48.18 | E13: 52.92 | F13: 57.44 | G13: 61.67 | H13: 78.04 | I13: 62.46 | K13: 2 | L13: 31.77 | M13: 44.14 | N13: 48.19 | O13: 56.39 | P13: 60.13 | Q13: 77.3 | R13: 56.41 | T13: 2 | U13: 38.22 | V13: 48.95 | W13: 53.62 | X13: 62.15 | Z13: =min(C13,L13) -> 31.77 | AA13: =min(D13,M13) -> 44.14 | AB13: =min(E13,N13) -> 48.19 | AC13: =min(F13,O13) -> 56.39 | AD13: =min(G13,P13) -> 60.13 | AE13: =min(H13,Q13) -> 77.3 | AF13: =min(I13,R13) -> 56.41
B14: 2.5 | C14: 37.01 | D14: 52.51 | E14: 58.73 | F14: 63.66 | G14: 68.27 | H14: 86.03 | I14: 69.18 | K14: 2.5 | L14: 33.76 | M14: 48.18 | N14: 53.44 | O14: 62.46 | P14: 66.48 | Q14: 85.23 | R14: 62.49 | T14: 2.5 | U14: 38.22 | V14: 48.95 | W14: 53.62 | X14: 62.15 | Z14: =min(C14,L14) -> 33.76 | AA14: =min(D14,M14) -> 48.18 | AB14: =min(E14,N14) -> 53.44 | AC14: =min(F14,O14) -> 62.46 | AD14: =min(G14,P14) -> 66.48 | AE14: =min(H14,Q14) -> 85.23 | AF14: =min(I14,R14) -> 62.49
B15: 3 | C15: 39.25 | D15: 57.04 | E15: 64.48 | F15: 69.81 | G15: 74.77 | H15: 93.64 | I15: 75.92 | K15: 3 | L15: 35.73 | M15: 52.19 | N15: 58.72 | O15: 68.51 | P15: 73.19 | Q15: 93.15 | R15: 68.54 | T15: 3 | U15: 69.02 | V15: 88.55 | W15: 96.25 | X15: 116.05 | Z15: =min(C15,L15) -> 35.73 | AA15: =min(D15,M15) -> 52.19 | AB15: =min(E15,N15) -> 58.72 | AC15: =min(F15,O15) -> 68.51 | AD15: =min(G15,P15) -> 73.19 | AE15: =min(H15,Q15) -> 93.15 | AF15: =min(I15,R15) -> 68.54
B16: 3.5 | C16: 41.48 | D16: 61.58 | E16: 70.23 | F16: 75.95 | G16: 81.27 | H16: 101.24 | I16: 82.66 | K16: 3.5 | L16: 37.7 | M16: 56.21 | N16: 64 | O16: 74.56 | P16: 79.9 | Q16: 101.07 | R16: 74.59 | T16: 3.5 | U16: 69.02 | V16: 88.55 | W16: 96.25 | X16: 116.05 | Z16: =min(C16,L16) -> 37.7 | AA16: =min(D16,M16) -> 56.21 | AB16: =min(E16,N16) -> 64 | AC16: =min(F16,O16) -> 74.56 | AD16: =min(G16,P16) -> 79.9 | AE16: =min(H16,Q16) -> 101.07 | AF16: =min(I16,R16) -> 74.59
B17: 4 | C17: 43.72 | D17: 66.12 | E17: 75.97 | F17: 82.1 | G17: 87.77 | H17: 108.85 | I17: 89.41 | K17: 4 | L17: 39.67 | M17: 60.22 | N17: 69.28 | O17: 80.61 | P17: 86.61 | Q17: 108.99 | R17: 80.64 | T17: 4 | U17: 69.02 | V17: 88.55 | W17: 96.25 | X17: 116.05 | Z17: =min(C17,L17) -> 39.67 | AA17: =min(D17,M17) -> 60.22 | AB17: =min(E17,N17) -> 69.28 | AC17: =min(F17,O17) -> 80.61 | AD17: =min(G17,P17) -> 86.61 | AE17: =min(H17,Q17) -> 108.85 | AF17: =min(I17,R17) -> 80.64
B18: 4.5 | C18: 45.95 | D18: 70.65 | E18: 81.72 | F18: 88.25 | G18: 94.27 | H18: 116.46 | I18: 96.15 | K18: 4.5 | L18: 41.63 | M18: 64.24 | N18: 74.56 | O18: 86.66 | P18: 93.32 | Q18: 116.91 | R18: 86.69 | T18: 4.5 | U18: 69.02 | V18: 88.55 | W18: 96.25 | X18: 116.05 | Z18: =min(C18,L18) -> 41.63 | AA18: =min(D18,M18) -> 64.24 | AB18: =min(E18,N18) -> 74.56 | AC18: =min(F18,O18) -> 86.66 | AD18: =min(G18,P18) -> 93.32 | AE18: =min(H18,Q18) -> 116.46 | AF18: =min(I18,R18) -> 86.69
B19: 5 | C19: 48.19 | D19: 75.19 | E19: 87.46 | F19: 94.4 | G19: 100.77 | H19: 124.07 | I19: 102.89 | K19: 5 | L19: 43.6 | M19: 68.25 | N19: 79.84 | O19: 92.71 | P19: 100.03 | Q19: 124.83 | R19: 92.74 | T19: 5 | U19: 69.02 | V19: 88.55 | W19: 96.25 | X19: 116.05 | Z19: =min(C19,L19) -> 43.6 | AA19: =min(D19,M19) -> 68.25 | AB19: =min(E19,N19) -> 79.84 | AC19: =min(F19,O19) -> 92.71 | AD19: =min(G19,P19) -> 100.03 | AE19: =min(H19,Q19) -> 124.07 | AF19: =min(I19,R19) -> 92.74
B20: 5.5 | C20: 50.01 | D20: 78.35 | E20: 91.18 | F20: 98.37 | G20: 106.37 | H20: 130.98 | I20: 107.14 | K20: 5.5 | L20: 45.26 | M20: 71.2 | N20: 83.19 | O20: 96.57 | P20: 105.54 | Q20: 131.46 | R20: 96.58 | T20: 5.5 | U20: 97.62 | V20: 124.3 | W20: 135.3 | X20: 152.35 | Z20: =min(C20,L20) -> 45.26 | AA20: =min(D20,M20) -> 71.2 | AB20: =min(E20,N20) -> 83.19 | AC20: =min(F20,O20) -> 96.57 | AD20: =min(G20,P20) -> 105.54 | AE20: =min(H20,Q20) -> 130.98 | AF20: =min(I20,R20) -> 96.58
B21: 6 | C21: 51.83 | D21: 81.51 | E21: 94.9 | F21: 102.34 | G21: 111.97 | H21: 137.89 | I21: 111.39 | K21: 6 | L21: 46.93 | M21: 74.15 | N21: 86.55 | O21: 100.43 | P21: 111.05 | Q21: 138.09 | R21: 100.42 | T21: 6 | U21: 97.62 | V21: 124.3 | W21: 135.3 | X21: 152.35 | Z21: =min(C21,L21) -> 46.93 | AA21: =min(D21,M21) -> 74.15 | AB21: =min(E21,N21) -> 86.55 | AC21: =min(F21,O21) -> 100.43 | AD21: =min(G21,P21) -> 111.05 | AE21: =min(H21,Q21) -> 137.89 | AF21: =min(I21,R21) -> 100.42
... B50: 20.5 | C50: 93.79 | D50: 155.61 | E50: 170.1 | F50: 187.74 | G50: 343.73 | H50: 361.64 | I50: 180.44 | K50: 20.5 | L50: 86.44 | M50: 146.33 | N50: 158.34 | O50: 183.41 | P50: 323.02 | Q50: 344.92 | R50: 184.11 | T50: 20.5 | U50: 136.12 | V50: 205.15 | W50: 193.6 | X50: 241.72 | Z50: =min(C50,L50) -> 86.44 | AA50: =min(D50,M50) -> 146.33 | AB50: =min(E50,N50) -> 158.34 | AC50: =min(F50,O50) -> 183.41 | AD50: =min(G50,P50) -> 323.02 | AE50: =min(H50,Q50) -> 344.92 | AF50: =min(I50,R50) -> 180.44
B51: 21 | C51: 93.87 | D51: 155.61 | E51: 170.1 | F51: 187.74 | G51: 343.77 | H51: 361.62 | I51: 180.6 | K51: 21 | L51: =$K51*L$73 -> 86.52 | M51: =$K51*M$73 -> 146.37 | N51: =$K51*N$73 -> 158.34 | O51: =$K51*O$73 -> 183.33 | P51: =$K51*P$73 -> 323.61 | Q51: =$K51*Q$73 -> 345.03 | R51: =$K51*R$73 -> 184.17 | T51: 21 | U51: 161.7 | V51: 212.1 | W51: 202.23 | X51: 244.23 | Z51: =min(C51,L51) -> 86.52 | AA51: =min(D51,M51) -> 146.37 | AB51: =min(E51,N51) -> 158.34 | AC51: =min(F51,O51) -> 183.33 | AD51: =min(G51,P51) -> 323.61 | AE51: =min(H51,Q51) -> 345.03 | AF51: =min(I51,R51) -> 180.6
B52: 21.5 | C52: 98.34 | D52: 163.02 | E52: 178.2 | F52: 196.68 | G52: 360.14 | H52: 378.84 | I52: 189.2 | K52: 21.5 | L52: 90.64 | M52: 153.34 | N52: 165.88 | O52: 192.06 | P52: 339.02 | Q52: 361.46 | R52: 192.94 | T52: 21.5 | U52: 169.4 | V52: 222.2 | W52: 211.86 | X52: 255.86 | Z52: =min(C52,L52) -> 90.64 | AA52: =min(D52,M52) -> 153.34 | AB52: =min(E52,N52) -> 165.88 | AC52: =min(F52,O52) -> 192.06 | AD52: =min(G52,P52) -> 339.02 | AE52: =min(H52,Q52) -> 361.46 | AF52: =min(I52,R52) -> 189.2
B53: 22 | C53: 98.34 | D53: 163.02 | E53: 178.2 | F53: 196.68 | G53: 360.14 | H53: 378.84 | I53: 189.2 | K53: 22 | L53: =$K53*L$73 -> 90.64 | M53: =$K53*M$73 -> 153.34 | N53: =$K53*N$73 -> 165.88 | O53: =$K53*O$73 -> 192.06 | P53: =$K53*P$73 -> 339.02 | Q53: =$K53*Q$73 -> 361.46 | R53: =$K53*R$73 -> 192.94 | T53: 22 | U53: 169.4 | V53: 222.2 | W53: 211.86 | X53: 255.86 | Z53: =min(C53,L53) -> 90.64 | AA53: =min(D53,M53) -> 153.34 | AB53: =min(E53,N53) -> 165.88 | AC53: =min(F53,O53) -> 192.06 | AD53: =min(G53,P53) -> 339.02 | AE53: =min(H53,Q53) -> 361.46 | AF53: =min(I53,R53) -> 189.2
B54: 22.5 | C54: 102.81 | D54: 170.43 | E54: 186.3 | F54: 205.62 | G54: 376.51 | H54: 396.06 | I54: 197.8 | K54: 22.5 | L54: 94.76 | M54: 160.31 | N54: 173.42 | O54: 200.79 | P54: 354.43 | Q54: 377.89 | R54: 201.71 | T54: 22.5 | U54: 177.1 | V54: 232.3 | W54: 221.49 | X54: 267.49 | Z54: =min(C54,L54) -> 94.76 | AA54: =min(D54,M54) -> 160.31 | AB54: =min(E54,N54) -> 173.42 | AC54: =min(F54,O54) -> 200.79 | AD54: =min(G54,P54) -> 354.43 | AE54: =min(H54,Q54) -> 377.89 | AF54: =min(I54,R54) -> 197.8
B55: 23 | C55: 102.81 | D55: 170.43 | E55: 186.3 | F55: 205.62 | G55: 376.51 | H55: 396.06 | I55: 197.8 | K55: 23 | L55: =$K55*L$73 -> 94.76 | M55: =$K55*M$73 -> 160.31 | N55: =$K55*N$73 -> 173.42 | O55: =$K55*O$73 -> 200.79 | P55: =$K55*P$73 -> 354.43 | Q55: =$K55*Q$73 -> 377.89 | R55: =$K55*R$73 -> 201.71 | T55: 23 | U55: 177.1 | V55: 232.3 | W55: 221.49 | X55: 267.49 | Z55: =min(C55,L55) -> 94.76 | AA55: =min(D55,M55) -> 160.31 | AB55: =min(E55,N55) -> 173.42 | AC55: =min(F55,O55) -> 200.79 | AD55: =min(G55,P55) -> 354.43 | AE55: =min(H55,Q55) -> 377.89 | AF55: =min(I55,R55) -> 197.8
B56: 23.5 | C56: 107.28 | D56: 177.84 | E56: 194.4 | F56: 214.56 | G56: 392.88 | H56: 413.28 | I56: 206.4 | K56: 23.5 | L56: 98.88 | M56: 167.28 | N56: 180.96 | O56: 209.52 | P56: 369.84 | Q56: 394.32 | R56: 210.48 | T56: 23.5 | U56: 184.8 | V56: 242.4 | W56: 231.12 | X56: 279.12 | Z56: =min(C56,L56) -> 98.88 | AA56: =min(D56,M56) -> 167.28 | AB56: =min(E56,N56) -> 180.96 | AC56: =min(F56,O56) -> 209.52 | AD56: =min(G56,P56) -> 369.84 | AE56: =min(H56,Q56) -> 394.32 | AF56: =min(I56,R56) -> 206.4
B57: 24 | C57: 107.28 | D57: 177.84 | E57: 194.4 | F57: 214.56 | G57: 392.88 | H57: 413.28 | I57: 206.4 | K57: 24 | L57: =$K57*L$73 -> 98.88 | M57: =$K57*M$73 -> 167.28 | N57: =$K57*N$73 -> 180.96 | O57: =$K57*O$73 -> 209.52 | P57: =$K57*P$73 -> 369.84 | Q57: =$K57*Q$73 -> 394.32 | R57: =$K57*R$73 -> 210.48 | T57: 24 | U57: 184.8 | V57: 242.4 | W57: 231.12 | X57: 279.12 | Z57: =min(C57,L57) -> 98.88 | AA57: =min(D57,M57) -> 167.28 | AB57: =min(E57,N57) -> 180.96 | AC57: =min(F57,O57) -> 209.52 | AD57: =min(G57,P57) -> 369.84 | AE57: =min(H57,Q57) -> 394.32 | AF57: =min(I57,R57) -> 206.4
B58: 24.5 | C58: 111.75 | D58: 185.25 | E58: 202.5 | F58: 223.5 | G58: 409.25 | H58: 430.5 | I58: 215 | K58: 24.5 | L58: 103 | M58: 174.25 | N58: 188.5 | O58: 218.25 | P58: 385.25 | Q58: 410.75 | R58: 219.25 | T58: 24.5 | U58: 192.5 | V58: 252.5 | W58: 240.75 | X58: 290.75 | Z58: =min(C58,L58) -> 103 | AA58: =min(D58,M58) -> 174.25 | AB58: =min(E58,N58) -> 188.5 | AC58: =min(F58,O58) -> 218.25 | AD58: =min(G58,P58) -> 385.25 | AE58: =min(H58,Q58) -> 410.75 | AF58: =min(I58,R58) -> 215
B59: 25 | C59: 111.75 | D59: 185.25 | E59: 202.5 | F59: 223.5 | G59: 409.25 | H59: 430.5 | I59: 215 | K59: 25 | L59: =$K59*L$73 -> 103 | M59: =$K59*M$73 -> 174.25 | N59: =$K59*N$73 -> 188.5 | O59: =$K59*O$73 -> 218.25 | P59: =$K59*P$73 -> 385.25 | Q59: =$K59*Q$73 -> 410.75 | R59: =$K59*R$73 -> 219.25 | T59: 25 | U59: 192.5 | V59: 252.5 | W59: 240.75 | X59: 290.75 | Z59: =min(C59,L59) -> 103 | AA59: =min(D59,M59) -> 174.25 | AB59: =min(E59,N59) -> 188.5 | AC59: =min(F59,O59) -> 218.25 | AD59: =min(G59,P59) -> 385.25 | AE59: =min(H59,Q59) -> 410.75 | AF59: =min(I59,R59) -> 215
B60: 25.5 | C60: 116.22 | D60: 192.66 | E60: 210.6 | F60: 232.44 | G60: 425.62 | H60: 447.72 | I60: 223.6 | K60: 25.5 | L60: 107.12 | M60: 181.22 | N60: 196.04 | O60: 226.98 | P60: 400.66 | Q60: 427.18 | R60: 228.02 | T60: 25.5 | U60: 200.2 | V60: 262.6 | W60: 250.38 | X60: 302.38 | Z60: =min(C60,L60) -> 107.12 | AA60: =min(D60,M60) -> 181.22 | AB60: =min(E60,N60) -> 196.04 | AC60: =min(F60,O60) -> 226.98 | AD60: =min(G60,P60) -> 400.66 | AE60: =min(H60,Q60) -> 427.18 | AF60: =min(I60,R60) -> 223.6
B61: 26 | C61: 116.22 | D61: 192.66 | E61: 210.6 | F61: 232.44 | G61: 425.62 | H61: 447.72 | I61: 223.6 | K61: 26 | L61: =$K61*L$73 -> 107.12 | M61: =$K61*M$73 -> 181.22 | N61: =$K61*N$73 -> 196.04 | O61: =$K61*O$73 -> 226.98 | P61: =$K61*P$73 -> 400.66 | Q61: =$K61*Q$73 -> 427.18 | R61: =$K61*R$73 -> 228.02 | T61: 26 | U61: 200.2 | V61: 262.6 | W61: 250.38 | X61: 302.38 | Z61: =min(C61,L61) -> 107.12 | AA61: =min(D61,M61) -> 181.22 | AB61: =min(E61,N61) -> 196.04 | AC61: =min(F61,O61) -> 226.98 | AD61: =min(G61,P61) -> 400.66 | AE61: =min(H61,Q61) -> 427.18 | AF61: =min(I61,R61) -> 223.6
B62: 26.5 | C62: 120.69 | D62: 200.07 | E62: 218.7 | F62: 241.38 | G62: 441.99 | H62: 464.94 | I62: 232.2 | K62: 26.5 | L62: 111.24 | M62: 188.19 | N62: 203.58 | O62: 235.71 | P62: 416.07 | Q62: 443.61 | R62: 236.79 | T62: 26.5 | U62: 207.9 | V62: 272.7 | W62: 260.01 | X62: 314.01 | Z62: =min(C62,L62) -> 111.24 | AA62: =min(D62,M62) -> 188.19 | AB62: =min(E62,N62) -> 203.58 | AC62: =min(F62,O62) -> 235.71 | AD62: =min(G62,P62) -> 416.07 | AE62: =min(H62,Q62) -> 443.61 | AF62: =min(I62,R62) -> 232.2
B63: 27 | C63: 120.69 | D63: 200.07 | E63: 218.7 | F63: 241.38 | G63: 441.99 | H63: 464.94 | I63: 232.2 | K63: 27 | L63: =$K63*L$73 -> 111.24 | M63: =$K63*M$73 -> 188.19 | N63: =$K63*N$73 -> 203.58 | O63: =$K63*O$73 -> 235.71 | P63: =$K63*P$73 -> 416.07 | Q63: =$K63*Q$73 -> 443.61 | R63: =$K63*R$73 -> 236.79 | T63: 27 | U63: 207.9 | V63: 272.7 | W63: 260.01 | X63: 314.01 | Z63: =min(C63,L63) -> 111.24 | AA63: =min(D63,M63) -> 188.19 | AB63: =min(E63,N63) -> 203.58 | AC63: =min(F63,O63) -> 235.71 | AD63: =min(G63,P63) -> 416.07 | AE63: =min(H63,Q63) -> 443.61 | AF63: =min(I63,R63) -> 232.2
B64: 27.5 | C64: 125.16 | D64: 207.48 | E64: 226.8 | F64: 250.32 | G64: 458.36 | H64: 482.16 | I64: 240.8 | K64: 27.5 | L64: 115.36 | M64: 195.16 | N64: 211.12 | O64: 244.44 | P64: 431.48 | Q64: 460.04 | R64: 245.56 | T64: 27.5 | U64: 215.6 | V64: 282.8 | W64: 269.64 | X64: 325.64 | Z64: =min(C64,L64) -> 115.36 | AA64: =min(D64,M64) -> 195.16 | AB64: =min(E64,N64) -> 211.12 | AC64: =min(F64,O64) -> 244.44 | AD64: =min(G64,P64) -> 431.48 | AE64: =min(H64,Q64) -> 460.04 | AF64: =min(I64,R64) -> 240.8
B65: 28 | C65: 125.16 | D65: 207.48 | E65: 226.8 | F65: 250.32 | G65: 458.36 | H65: 482.16 | I65: 240.8 | K65: 28 | L65: =$K65*L$73 -> 115.36 | M65: =$K65*M$73 -> 195.16 | N65: =$K65*N$73 -> 211.12 | O65: =$K65*O$73 -> 244.44 | P65: =$K65*P$73 -> 431.48 | Q65: =$K65*Q$73 -> 460.04 | R65: =$K65*R$73 -> 245.56 | T65: 28 | U65: 215.6 | V65: 282.8 | W65: 269.64 | X65: 325.64 | Z65: =min(C65,L65) -> 115.36 | AA65: =min(D65,M65) -> 195.16 | AB65: =min(E65,N65) -> 211.12 | AC65: =min(F65,O65) -> 244.44 | AD65: =min(G65,P65) -> 431.48 | AE65: =min(H65,Q65) -> 460.04 | AF65: =min(I65,R65) -> 240.8
B66: 28.5 | C66: 129.63 | D66: 214.89 | E66: 234.9 | F66: 259.26 | G66: 474.73 | H66: 499.38 | I66: 249.4 | K66: 28.5 | L66: 119.48 | M66: 202.13 | N66: 218.66 | O66: 253.17 | P66: 446.89 | Q66: 476.47 | R66: 254.33 | T66: 28.5 | U66: 223.3 | V66: 292.9 | W66: 279.27 | X66: 337.27 | Z66: =min(C66,L66) -> 119.48 | AA66: =min(D66,M66) -> 202.13 | AB66: =min(E66,N66) -> 218.66 | AC66: =min(F66,O66) -> 253.17 | AD66: =min(G66,P66) -> 446.89 | AE66: =min(H66,Q66) -> 476.47 | AF66: =min(I66,R66) -> 249.4
B67: 29 | C67: 129.63 | D67: 214.89 | E67: 234.9 | F67: 259.26 | G67: 474.73 | H67: 499.38 | I67: 249.4 | K67: 29 | L67: =$K67*L$73 -> 119.48 | M67: =$K67*M$73 -> 202.13 | N67: =$K67*N$73 -> 218.66 | O67: =$K67*O$73 -> 253.17 | P67: =$K67*P$73 -> 446.89 | Q67: =$K67*Q$73 -> 476.47 | R67: =$K67*R$73 -> 254.33 | T67: 29 | U67: 223.3 | V67: 292.9 | W67: 279.27 | X67: 337.27 | Z67: =min(C67,L67) -> 119.48 | AA67: =min(D67,M67) -> 202.13 | AB67: =min(E67,N67) -> 218.66 | AC67: =min(F67,O67) -> 253.17 | AD67: =min(G67,P67) -> 446.89 | AE67: =min(H67,Q67) -> 476.47 | AF67: =min(I67,R67) -> 249.4
B68: 29.5 | C68: 134.1 | D68: 222.3 | E68: 243 | F68: 268.2 | G68: 491.1 | H68: 516.6 | I68: 258 | K68: 29.5 | L68: 123.6 | M68: 209.1 | N68: 226.2 | O68: 261.9 | P68: 462.3 | Q68: 492.9 | R68: 263.1 | T68: 29.5 | U68: 231 | V68: 303 | W68: 288.9 | X68: 348.9 | Z68: =min(C68,L68) -> 123.6 | AA68: =min(D68,M68) -> 209.1 | AB68: =min(E68,N68) -> 226.2 | AC68: =min(F68,O68) -> 261.9 | AD68: =min(G68,P68) -> 462.3 | AE68: =min(H68,Q68) -> 492.9 | AF68: =min(I68,R68) -> 258
B69: 30 | C69: 134.1 | D69: 222.3 | E69: 243 | F69: 268.2 | G69: 491.1 | H69: 516.6 | I69: 258 | K69: 30 | L69: =$K69*L$73 -> 123.6 | M69: =$K69*M$73 -> 209.1 | N69: =$K69*N$73 -> 226.2 | O69: =$K69*O$73 -> 261.9 | P69: =$K69*P$73 -> 462.3 | Q69: =$K69*Q$73 -> 492.9 | R69: =$K69*R$73 -> 263.1 | T69: 30 | U69: 231 | V69: 303 | W69: 288.9 | X69: 348.9 | Z69: =min(C69,L69) -> 123.6 | AA69: =min(D69,M69) -> 209.1 | AB69: =min(E69,N69) -> 226.2 | AC69: =min(F69,O69) -> 261.9 | AD69: =min(G69,P69) -> 462.3 | AE69: =min(H69,Q69) -> 492.9 | AF69: =min(I69,R69) -> 258
...

Sheet UPS
C2: Standard | K2: Express
C3: Zone 1 | D3: Zone 2 | E3: Zone 3 | F3: Zone 4 | G3: Zone 5 | H3: Zone 6 | K3: Zone 1 | L3: Zone 2 | M3: Zone 3 | N3: Zone 4 | O3: Zone 5 | P3: Zone 6
J4: Sobre | K4: 15.89 | L4: 27.38 | M4: 22.59 | N4: 27.51 | O4: 35.97 | P4: 47.19
J5: 0.5 | K5: 16.77 | L5: 23.55 | M5: 25.1 | N5: 34.59 | O5: 40.02 | P5: 47.61
J6: 1 | K6: 19.65 | L6: 27.99 | M6: 32.63 | N6: 43.64 | O6: 52.47 | P6: 59.91
J7: 1.5 | K7: 23.57 | L7: 31.65 | M7: 43.05 | N7: 52.68 | O7: 61.56 | P7: 69.95
J8: 2 | K8: 27.89 | L8: 35.24 | M8: 53.34 | N8: 61.58 | O8: 70.41 | P8: 80.19
J9: 2.5 | K9: 31.08 | L9: 38.94 | M9: 63.54 | N9: 71.28 | O9: 82.14 | P9: 90.41
B10: 0.5 | C10: 18.02 | D10: 25.41 | E10: 24.83 | F10: 30.56 | G10: 41.28 | H10: 52.66 | J10: 0.5 | K10: 19.2 | L10: 27.03 | M10: 26.39 | N10: 32.51 | O10: 43.91 | P10: 56.04
B11: 1 | C11: 21.03 | D11: 30.05 | E11: 30.69 | F11: 37.78 | G11: 52.13 | H11: 62.18 | J11: 1 | K11: 22.35 | L11: 31.95 | M11: 32.65 | N11: 40.18 | O11: 55.46 | P11: 66.14
B12: 1.5 | C12: 24.04 | D12: 33.33 | E12: 36.73 | F12: 45.08 | G12: 60 | H12: 69.94 | J12: 1.5 | K12: 25.58 | L12: 35.45 | M12: 39.06 | N12: 48 | O12: 63.8 | P12: 74.43
B13: 2 | C13: 27.27 | D13: 37.4 | E13: 42.52 | F13: 52.31 | G13: 67.65 | H13: 77.75 | J13: 2 | K13: 29.02 | L13: 39.8 | M13: 45.21 | N13: 55.64 | O13: 72.01 | P13: 82.73
B14: 2.5 | C14: 30.02 | D14: 42.24 | E14: 48.36 | F14: 59.5 | G14: 75.82 | H14: 85.71 | J14: 2.5 | K14: 31.94 | L14: 44.97 | M14: 51.45 | N14: 63.28 | O14: 80.64 | P14: 91.21
B15: 3 | C15: 31.79 | D15: 46.97 | E15: 54.21 | F15: 66.48 | G15: 81.71 | H15: 92.76 | J15: 3 | K15: 33.83 | L15: 49.95 | M15: 57.65 | N15: 70.75 | O15: 86.91 | P15: 98.7
B16: 3.5 | C16: 33.75 | D16: 52.41 | E16: 60.08 | F16: 73.65 | G16: 88.58 | H16: 99.96 | J16: 3.5 | K16: 35.93 | L16: 55.79 | M16: 63.9 | N16: 78.36 | O16: 94.22 | P16: 106.33
B17: 4 | C17: 35.74 | D17: 56.66 | E17: 65.4 | F17: 80.2 | G17: 95.39 | H17: 106.94 | J17: 4 | K17: 38.03 | L17: 60.26 | M17: 69.56 | N17: 85.32 | O17: 101.5 | P17: 113.79
B18: 4.5 | C18: 37.86 | D18: 60.56 | E18: 70.74 | F18: 86.58 | G18: 102.15 | H18: 114.21 | J18: 4.5 | K18: 40.27 | L18: 64.46 | M18: 75.27 | N18: 92.11 | O18: 108.71 | P18: 121.47
B19: 5 | C19: 40.07 | D19: 64.73 | E19: 77.89 | F19: 95.58 | G19: 108.95 | H19: 126.41 | J19: 5 | K19: 42.64 | L19: 68.84 | M19: 82.85 | N19: 101.65 | O19: 115.88 | P19: 134.46
B20: 5.5 | C20: 41.99 | D20: 68.37 | E20: 85.62 | F20: 104.86 | G20: 113.24 | H20: 126.88 | J20: 5.5 | K20: 44.67 | L20: 72.77 | M20: 91.08 | N20: 111.57 | O20: 120.46 | P20: 134.99
B21: 6 | C21: 44.07 | D21: 72.08 | E21: 90.57 | F21: 110.96 | G21: 117.53 | H21: 132.05 | J21: 6 | K21: 46.88 | L21: 76.68 | M21: 96.36 | N21: 118.01 | O21: 125.02 | P21: 140.48
... B72: 31.5 | C72: 142 | D72: 198.87 | E72: 278.23 | F72: 333.8 | G72: 337.27 | H72: 361.13 | J72: 31.5 | K72: 151.09 | L72: 211.53 | M72: 295.99 | N72: 355.11 | O72: 358.81 | P72: 384.18
B73: 32 - 44 | C73: 4.52 | D73: 6.34 | E73: 8.85 | F73: 10.61 | G73: 10.73 | H73: 11.49 | J73: 32 - 44 | K73: 4.81 | L73: 6.73 | M73: 9.41 | N73: 11.28 | O73: 11.41 | P73: 12.21
B74: 45 - 67 | C74: 4.52 | D74: 6.34 | E74: 8.85 | F74: 10.61 | G74: 10.73 | H74: 11.49 | J74: 45 - 67 | K74: 4.81 | L74: 6.73 | M74: 9.41 | N74: 11.28 | O74: 11.41 | P74: 12.21
B75: 68 - 70 | C75: 4.52 | D75: 6.34 | E75: 8.85 | F75: 10.61 | G75: 10.73 | H75: 11.49 | J75: 68 - 70 | K75: 4.81 | L75: 6.73 | M75: 9.41 | N75: 11.28 | O75: 11.41 | P75: 12.21
B76: 71 - 99 | C76: 4.52 | D76: 6.34 | E76: 8.85 | F76: 10.61 | G76: 10.73 | H76: 11.49 | J76: 71 - 99 | K76: 4.81 | L76: 6.73 | M76: 9.41 | N76: 11.28 | O76: 11.41 | P76: 12.21
B77: 100 - 299 | C77: 4.52 | D77: 6.34 | E77: 8.85 | F77: 10.61 | G77: 10.73 | H77: 11.49 | J77: 100 - 299 | K77: 4.81 | L77: 6.73 | M77: 9.41 | N77: 11.28 | O77: 11.41 | P77: 12.21
B78: 300 - 499 | C78: 4.52 | D78: 6.34 | E78: 8.85 | F78: 10.61 | G78: 10.73 | H78: 11.49 | J78: 300 - 499 | K78: 4.81 | L78: 6.73 | M78: 9.41 | N78: 11.28 | O78: 11.41 | P78: 12.21
B79: 500 - 999 | C79: 4.52 | D79: 6.34 | E79: 8.85 | F79: 10.61 | G79: 10.73 | H79: 11.49 | J79: 500 - 999 | K79: 4.81 | L79: 6.73 | M79: 9.41 | N79: 11.28 | O79: 11.41 | P79: 12.21
B80: +1,000 | C80: 4.52 | D80: 6.34 | E80: 8.85 | F80: 10.61 | G80: 10.73 | H80: 11.49 | J80: +1,000 | K80: 4.81 | L80: 6.73 | M80: 9.41 | N80: 11.28 | O80: 11.41 | P80: 12.21

Sheet Areas
C3: UPS | D3: FedEx | E3: 3onne3t plus
B4: Afganistán | C4: 6 | D4: 6 | E4: 4
B5: Albania | C5: 6 | D5: 5 | E5: 4
B6: Alemania | C6: 5 | D6: 4 | E6: 2
B7: Angola | C7: 6 | D7: 6 | E7: 4
B8: Anguila | C8: 2 | D8: 3 | E8: 1
B9: Antigua y Barbuda | C9: 2 | D9: 3 | E9: 1
B10: Arabia Saudita | C10: 6 | D10: 6 | E10: 4
B11: Argelia | C11: 6 | D11: 6 | E11: 4
